03/04/2023 09:35:16 AM : logging_confiq.logger : 
Traceback (most recent call last):
  File "C:\Users\RJ EMPIRE\Desktop\Django\FundooNotes\Notes\views.py", line 29, in post
    serializer.save()
  File "C:\Users\RJ EMPIRE\Desktop\env\env03\Lib\site-packages\rest_framework\serializers.py", line 212, in save
    self.instance = self.create(validated_data)
                    ^^^^^^^^^^^^^^^^^^^^^^^^^^^
  File "C:\Users\RJ EMPIRE\Desktop\Django\FundooNotes\Notes\serializers.py", line 24, in create
    notes = Notes.objects.create(**validated_data)
            ^^^^^^^^^^^^^^^^^^^^^^^^^^^^^^^^^^^^^^
  File "C:\Users\RJ EMPIRE\Desktop\env\env03\Lib\site-packages\django\db\models\manager.py", line 85, in manager_method
    return getattr(self.get_queryset(), name)(*args, **kwargs)
           ^^^^^^^^^^^^^^^^^^^^^^^^^^^^^^^^^^^^^^^^^^^^^^^^^^^
  File "C:\Users\RJ EMPIRE\Desktop\env\env03\Lib\site-packages\django\db\models\query.py", line 669, in create
    obj = self.model(**kwargs)
          ^^^^^^^^^^^^^^^^^^^^
  File "C:\Users\RJ EMPIRE\Desktop\env\env03\Lib\site-packages\django\db\models\base.py", line 562, in __init__
    _setattr(self, prop, value)
  File "C:\Users\RJ EMPIRE\Desktop\env\env03\Lib\site-packages\django\db\models\fields\related_descriptors.py", line 597, in __set__
    raise TypeError(
TypeError: Direct assignment to the forward side of a many-to-many set is prohibited. Use collaborator.set() instead.
03/04/2023 09:35:16 AM : logging_confiq.logger : 
Traceback (most recent call last):
  File "C:\Users\RJ EMPIRE\Desktop\Django\FundooNotes\Notes\views.py", line 29, in post
    serializer.save()
  File "C:\Users\RJ EMPIRE\Desktop\env\env03\Lib\site-packages\rest_framework\serializers.py", line 212, in save
    self.instance = self.create(validated_data)
                    ^^^^^^^^^^^^^^^^^^^^^^^^^^^
  File "C:\Users\RJ EMPIRE\Desktop\Django\FundooNotes\Notes\serializers.py", line 24, in create
    notes = Notes.objects.create(**validated_data)
            ^^^^^^^^^^^^^^^^^^^^^^^^^^^^^^^^^^^^^^
  File "C:\Users\RJ EMPIRE\Desktop\env\env03\Lib\site-packages\django\db\models\manager.py", line 85, in manager_method
    return getattr(self.get_queryset(), name)(*args, **kwargs)
           ^^^^^^^^^^^^^^^^^^^^^^^^^^^^^^^^^^^^^^^^^^^^^^^^^^^
  File "C:\Users\RJ EMPIRE\Desktop\env\env03\Lib\site-packages\django\db\models\query.py", line 669, in create
    obj = self.model(**kwargs)
          ^^^^^^^^^^^^^^^^^^^^
  File "C:\Users\RJ EMPIRE\Desktop\env\env03\Lib\site-packages\django\db\models\base.py", line 562, in __init__
    _setattr(self, prop, value)
  File "C:\Users\RJ EMPIRE\Desktop\env\env03\Lib\site-packages\django\db\models\fields\related_descriptors.py", line 597, in __set__
    raise TypeError(
TypeError: Direct assignment to the forward side of a many-to-many set is prohibited. Use collaborator.set() instead.
03/04/2023 10:12:10 AM : logging_confiq.logger : 
Traceback (most recent call last):
  File "C:\Users\RJ EMPIRE\Desktop\Django\FundooNotes\Notes\views.py", line 29, in post
    serializer.save()
  File "C:\Users\RJ EMPIRE\Desktop\env\env03\Lib\site-packages\rest_framework\serializers.py", line 212, in save
    self.instance = self.create(validated_data)
                    ^^^^^^^^^^^^^^^^^^^^^^^^^^^
  File "C:\Users\RJ EMPIRE\Desktop\Django\FundooNotes\Notes\serializers.py", line 24, in create
    notes = Notes.objects.create(**validated_data)
            ^^^^^^^^^^^^^^^^^^^^^^^^^^^^^^^^^^^^^^
  File "C:\Users\RJ EMPIRE\Desktop\env\env03\Lib\site-packages\django\db\models\manager.py", line 85, in manager_method
    return getattr(self.get_queryset(), name)(*args, **kwargs)
           ^^^^^^^^^^^^^^^^^^^^^^^^^^^^^^^^^^^^^^^^^^^^^^^^^^^
  File "C:\Users\RJ EMPIRE\Desktop\env\env03\Lib\site-packages\django\db\models\query.py", line 669, in create
    obj = self.model(**kwargs)
          ^^^^^^^^^^^^^^^^^^^^
  File "C:\Users\RJ EMPIRE\Desktop\env\env03\Lib\site-packages\django\db\models\base.py", line 562, in __init__
    _setattr(self, prop, value)
  File "C:\Users\RJ EMPIRE\Desktop\env\env03\Lib\site-packages\django\db\models\fields\related_descriptors.py", line 597, in __set__
    raise TypeError(
TypeError: Direct assignment to the forward side of a many-to-many set is prohibited. Use collaborator.set() instead.
03/04/2023 10:12:10 AM : logging_confiq.logger : 
Traceback (most recent call last):
  File "C:\Users\RJ EMPIRE\Desktop\Django\FundooNotes\Notes\views.py", line 29, in post
    serializer.save()
  File "C:\Users\RJ EMPIRE\Desktop\env\env03\Lib\site-packages\rest_framework\serializers.py", line 212, in save
    self.instance = self.create(validated_data)
                    ^^^^^^^^^^^^^^^^^^^^^^^^^^^
  File "C:\Users\RJ EMPIRE\Desktop\Django\FundooNotes\Notes\serializers.py", line 24, in create
    notes = Notes.objects.create(**validated_data)
            ^^^^^^^^^^^^^^^^^^^^^^^^^^^^^^^^^^^^^^
  File "C:\Users\RJ EMPIRE\Desktop\env\env03\Lib\site-packages\django\db\models\manager.py", line 85, in manager_method
    return getattr(self.get_queryset(), name)(*args, **kwargs)
           ^^^^^^^^^^^^^^^^^^^^^^^^^^^^^^^^^^^^^^^^^^^^^^^^^^^
  File "C:\Users\RJ EMPIRE\Desktop\env\env03\Lib\site-packages\django\db\models\query.py", line 669, in create
    obj = self.model(**kwargs)
          ^^^^^^^^^^^^^^^^^^^^
  File "C:\Users\RJ EMPIRE\Desktop\env\env03\Lib\site-packages\django\db\models\base.py", line 562, in __init__
    _setattr(self, prop, value)
  File "C:\Users\RJ EMPIRE\Desktop\env\env03\Lib\site-packages\django\db\models\fields\related_descriptors.py", line 597, in __set__
    raise TypeError(
TypeError: Direct assignment to the forward side of a many-to-many set is prohibited. Use collaborator.set() instead.
03/04/2023 10:27:38 AM : logging_confiq.logger : 
Traceback (most recent call last):
  File "C:\Users\RJ EMPIRE\Desktop\Django\FundooNotes\Notes\views.py", line 28, in post
    serializer.is_valid(raise_exception=True)
  File "C:\Users\RJ EMPIRE\Desktop\env\env03\Lib\site-packages\rest_framework\serializers.py", line 235, in is_valid
    raise ValidationError(self.errors)
rest_framework.exceptions.ValidationError: {'title': [ErrorDetail(string='This field is required.', code='required')], 'collaborator': [ErrorDetail(string='This field is required.', code='required')]}
03/04/2023 10:27:38 AM : logging_confiq.logger : 
Traceback (most recent call last):
  File "C:\Users\RJ EMPIRE\Desktop\Django\FundooNotes\Notes\views.py", line 28, in post
    serializer.is_valid(raise_exception=True)
  File "C:\Users\RJ EMPIRE\Desktop\env\env03\Lib\site-packages\rest_framework\serializers.py", line 235, in is_valid
    raise ValidationError(self.errors)
rest_framework.exceptions.ValidationError: {'title': [ErrorDetail(string='This field is required.', code='required')], 'collaborator': [ErrorDetail(string='This field is required.', code='required')]}
03/04/2023 10:27:39 AM : logging_confiq.logger : 
Traceback (most recent call last):
  File "C:\Users\RJ EMPIRE\Desktop\Django\FundooNotes\Notes\views.py", line 28, in post
    serializer.is_valid(raise_exception=True)
  File "C:\Users\RJ EMPIRE\Desktop\env\env03\Lib\site-packages\rest_framework\serializers.py", line 235, in is_valid
    raise ValidationError(self.errors)
rest_framework.exceptions.ValidationError: {'collaborator': [ErrorDetail(string='This field is required.', code='required')]}
03/04/2023 10:27:39 AM : logging_confiq.logger : 
Traceback (most recent call last):
  File "C:\Users\RJ EMPIRE\Desktop\Django\FundooNotes\Notes\views.py", line 28, in post
    serializer.is_valid(raise_exception=True)
  File "C:\Users\RJ EMPIRE\Desktop\env\env03\Lib\site-packages\rest_framework\serializers.py", line 235, in is_valid
    raise ValidationError(self.errors)
rest_framework.exceptions.ValidationError: {'collaborator': [ErrorDetail(string='This field is required.', code='required')]}
03/04/2023 10:27:40 AM : logging_confiq.logger : 
Traceback (most recent call last):
  File "C:\Users\RJ EMPIRE\Desktop\Django\FundooNotes\Notes\views.py", line 28, in post
    serializer.is_valid(raise_exception=True)
  File "C:\Users\RJ EMPIRE\Desktop\env\env03\Lib\site-packages\rest_framework\serializers.py", line 235, in is_valid
    raise ValidationError(self.errors)
rest_framework.exceptions.ValidationError: {'collaborator': [ErrorDetail(string='This field is required.', code='required')]}
03/04/2023 10:27:40 AM : logging_confiq.logger : 
Traceback (most recent call last):
  File "C:\Users\RJ EMPIRE\Desktop\Django\FundooNotes\Notes\views.py", line 28, in post
    serializer.is_valid(raise_exception=True)
  File "C:\Users\RJ EMPIRE\Desktop\env\env03\Lib\site-packages\rest_framework\serializers.py", line 235, in is_valid
    raise ValidationError(self.errors)
rest_framework.exceptions.ValidationError: {'collaborator': [ErrorDetail(string='This field is required.', code='required')]}
03/04/2023 10:27:46 AM : logging_confiq.logger : 
Traceback (most recent call last):
  File "C:\Users\RJ EMPIRE\Desktop\Django\FundooNotes\Notes\views.py", line 28, in post
    serializer.is_valid(raise_exception=True)
  File "C:\Users\RJ EMPIRE\Desktop\env\env03\Lib\site-packages\rest_framework\serializers.py", line 235, in is_valid
    raise ValidationError(self.errors)
rest_framework.exceptions.ValidationError: {'collaborator': [ErrorDetail(string='This field is required.', code='required')]}
03/04/2023 10:27:46 AM : logging_confiq.logger : 
Traceback (most recent call last):
  File "C:\Users\RJ EMPIRE\Desktop\Django\FundooNotes\Notes\views.py", line 28, in post
    serializer.is_valid(raise_exception=True)
  File "C:\Users\RJ EMPIRE\Desktop\env\env03\Lib\site-packages\rest_framework\serializers.py", line 235, in is_valid
    raise ValidationError(self.errors)
rest_framework.exceptions.ValidationError: {'collaborator': [ErrorDetail(string='This field is required.', code='required')]}
03/04/2023 10:27:46 AM : logging_confiq.logger : 
Traceback (most recent call last):
  File "C:\Users\RJ EMPIRE\Desktop\Django\FundooNotes\Notes\views.py", line 28, in post
    serializer.is_valid(raise_exception=True)
  File "C:\Users\RJ EMPIRE\Desktop\env\env03\Lib\site-packages\rest_framework\serializers.py", line 235, in is_valid
    raise ValidationError(self.errors)
rest_framework.exceptions.ValidationError: {'collaborator': [ErrorDetail(string='This field is required.', code='required')]}
03/04/2023 10:27:46 AM : logging_confiq.logger : 
Traceback (most recent call last):
  File "C:\Users\RJ EMPIRE\Desktop\Django\FundooNotes\Notes\views.py", line 28, in post
    serializer.is_valid(raise_exception=True)
  File "C:\Users\RJ EMPIRE\Desktop\env\env03\Lib\site-packages\rest_framework\serializers.py", line 235, in is_valid
    raise ValidationError(self.errors)
rest_framework.exceptions.ValidationError: {'collaborator': [ErrorDetail(string='This field is required.', code='required')]}
03/04/2023 10:27:47 AM : logging_confiq.logger : 
Traceback (most recent call last):
  File "C:\Users\RJ EMPIRE\Desktop\Django\FundooNotes\user_auth\views.py", line 87, in post
    serializer.save()
  File "C:\Users\RJ EMPIRE\Desktop\env\env03\Lib\site-packages\rest_framework\serializers.py", line 212, in save
    self.instance = self.create(validated_data)
                    ^^^^^^^^^^^^^^^^^^^^^^^^^^^
  File "C:\Users\RJ EMPIRE\Desktop\Django\FundooNotes\user_auth\serializers.py", line 32, in create
    raise serializers.ValidationError("Incorrect Credentials")
rest_framework.exceptions.ValidationError: [ErrorDetail(string='Incorrect Credentials', code='invalid')]
03/04/2023 10:27:47 AM : logging_confiq.logger : 
Traceback (most recent call last):
  File "C:\Users\RJ EMPIRE\Desktop\Django\FundooNotes\user_auth\views.py", line 87, in post
    serializer.save()
  File "C:\Users\RJ EMPIRE\Desktop\env\env03\Lib\site-packages\rest_framework\serializers.py", line 212, in save
    self.instance = self.create(validated_data)
                    ^^^^^^^^^^^^^^^^^^^^^^^^^^^
  File "C:\Users\RJ EMPIRE\Desktop\Django\FundooNotes\user_auth\serializers.py", line 32, in create
    raise serializers.ValidationError("Incorrect Credentials")
rest_framework.exceptions.ValidationError: [ErrorDetail(string='Incorrect Credentials', code='invalid')]
03/04/2023 10:27:47 AM : logging_confiq.logger : 
Traceback (most recent call last):
  File "C:\Users\RJ EMPIRE\Desktop\Django\FundooNotes\user_auth\views.py", line 85, in post
    serializer.is_valid(raise_exception=True)
  File "C:\Users\RJ EMPIRE\Desktop\env\env03\Lib\site-packages\rest_framework\serializers.py", line 235, in is_valid
    raise ValidationError(self.errors)
rest_framework.exceptions.ValidationError: {'password': [ErrorDetail(string='This field is required.', code='required')]}
03/04/2023 10:27:47 AM : logging_confiq.logger : 
Traceback (most recent call last):
  File "C:\Users\RJ EMPIRE\Desktop\Django\FundooNotes\user_auth\views.py", line 85, in post
    serializer.is_valid(raise_exception=True)
  File "C:\Users\RJ EMPIRE\Desktop\env\env03\Lib\site-packages\rest_framework\serializers.py", line 235, in is_valid
    raise ValidationError(self.errors)
rest_framework.exceptions.ValidationError: {'password': [ErrorDetail(string='This field is required.', code='required')]}
03/04/2023 10:27:49 AM : logging_confiq.logger : 
Traceback (most recent call last):
  File "C:\Users\RJ EMPIRE\Desktop\Django\FundooNotes\user_auth\views.py", line 28, in post
    serializer.is_valid(raise_exception=True)
  File "C:\Users\RJ EMPIRE\Desktop\env\env03\Lib\site-packages\rest_framework\serializers.py", line 235, in is_valid
    raise ValidationError(self.errors)
rest_framework.exceptions.ValidationError: {'address': [ErrorDetail(string='This field is required.', code='required')], 'username': [ErrorDetail(string='This field is required.', code='required')], 'password': [ErrorDetail(string='This field is required.', code='required')]}
03/04/2023 10:27:49 AM : logging_confiq.logger : 
Traceback (most recent call last):
  File "C:\Users\RJ EMPIRE\Desktop\Django\FundooNotes\user_auth\views.py", line 28, in post
    serializer.is_valid(raise_exception=True)
  File "C:\Users\RJ EMPIRE\Desktop\env\env03\Lib\site-packages\rest_framework\serializers.py", line 235, in is_valid
    raise ValidationError(self.errors)
rest_framework.exceptions.ValidationError: {'address': [ErrorDetail(string='This field is required.', code='required')], 'username': [ErrorDetail(string='This field is required.', code='required')], 'password': [ErrorDetail(string='This field is required.', code='required')]}
03/04/2023 10:27:50 AM : logging_confiq.logger : 
Traceback (most recent call last):
  File "C:\Users\RJ EMPIRE\Desktop\Django\FundooNotes\user_auth\views.py", line 28, in post
    serializer.is_valid(raise_exception=True)
  File "C:\Users\RJ EMPIRE\Desktop\env\env03\Lib\site-packages\rest_framework\serializers.py", line 235, in is_valid
    raise ValidationError(self.errors)
rest_framework.exceptions.ValidationError: {'username': [ErrorDetail(string='This field may not be blank.', code='blank')]}
03/04/2023 10:27:50 AM : logging_confiq.logger : 
Traceback (most recent call last):
  File "C:\Users\RJ EMPIRE\Desktop\Django\FundooNotes\user_auth\views.py", line 28, in post
    serializer.is_valid(raise_exception=True)
  File "C:\Users\RJ EMPIRE\Desktop\env\env03\Lib\site-packages\rest_framework\serializers.py", line 235, in is_valid
    raise ValidationError(self.errors)
rest_framework.exceptions.ValidationError: {'username': [ErrorDetail(string='This field may not be blank.', code='blank')]}
03/04/2023 10:36:02 AM : logging_confiq.logger : 
Traceback (most recent call last):
  File "C:\Users\RJ EMPIRE\Desktop\Django\FundooNotes\Notes\views.py", line 28, in post
    serializer.is_valid(raise_exception=True)
  File "C:\Users\RJ EMPIRE\Desktop\env\env03\Lib\site-packages\rest_framework\serializers.py", line 235, in is_valid
    raise ValidationError(self.errors)
rest_framework.exceptions.ValidationError: {'title': [ErrorDetail(string='This field is required.', code='required')], 'collaborator': [ErrorDetail(string='This field is required.', code='required')]}
03/04/2023 10:36:02 AM : logging_confiq.logger : 
Traceback (most recent call last):
  File "C:\Users\RJ EMPIRE\Desktop\Django\FundooNotes\Notes\views.py", line 28, in post
    serializer.is_valid(raise_exception=True)
  File "C:\Users\RJ EMPIRE\Desktop\env\env03\Lib\site-packages\rest_framework\serializers.py", line 235, in is_valid
    raise ValidationError(self.errors)
rest_framework.exceptions.ValidationError: {'title': [ErrorDetail(string='This field is required.', code='required')], 'collaborator': [ErrorDetail(string='This field is required.', code='required')]}
03/04/2023 10:36:04 AM : logging_confiq.logger : 
Traceback (most recent call last):
  File "C:\Users\RJ EMPIRE\Desktop\Django\FundooNotes\Notes\views.py", line 28, in post
    serializer.is_valid(raise_exception=True)
  File "C:\Users\RJ EMPIRE\Desktop\env\env03\Lib\site-packages\rest_framework\serializers.py", line 235, in is_valid
    raise ValidationError(self.errors)
rest_framework.exceptions.ValidationError: {'collaborator': [ErrorDetail(string='This field is required.', code='required')]}
03/04/2023 10:36:04 AM : logging_confiq.logger : 
Traceback (most recent call last):
  File "C:\Users\RJ EMPIRE\Desktop\Django\FundooNotes\Notes\views.py", line 28, in post
    serializer.is_valid(raise_exception=True)
  File "C:\Users\RJ EMPIRE\Desktop\env\env03\Lib\site-packages\rest_framework\serializers.py", line 235, in is_valid
    raise ValidationError(self.errors)
rest_framework.exceptions.ValidationError: {'collaborator': [ErrorDetail(string='This field is required.', code='required')]}
03/04/2023 10:36:05 AM : logging_confiq.logger : 
Traceback (most recent call last):
  File "C:\Users\RJ EMPIRE\Desktop\Django\FundooNotes\Notes\views.py", line 28, in post
    serializer.is_valid(raise_exception=True)
  File "C:\Users\RJ EMPIRE\Desktop\env\env03\Lib\site-packages\rest_framework\serializers.py", line 235, in is_valid
    raise ValidationError(self.errors)
rest_framework.exceptions.ValidationError: {'collaborator': [ErrorDetail(string='This field is required.', code='required')]}
03/04/2023 10:36:05 AM : logging_confiq.logger : 
Traceback (most recent call last):
  File "C:\Users\RJ EMPIRE\Desktop\Django\FundooNotes\Notes\views.py", line 28, in post
    serializer.is_valid(raise_exception=True)
  File "C:\Users\RJ EMPIRE\Desktop\env\env03\Lib\site-packages\rest_framework\serializers.py", line 235, in is_valid
    raise ValidationError(self.errors)
rest_framework.exceptions.ValidationError: {'collaborator': [ErrorDetail(string='This field is required.', code='required')]}
03/04/2023 10:36:08 AM : logging_confiq.logger : 
Traceback (most recent call last):
  File "C:\Users\RJ EMPIRE\Desktop\Django\FundooNotes\Notes\views.py", line 28, in post
    serializer.is_valid(raise_exception=True)
  File "C:\Users\RJ EMPIRE\Desktop\env\env03\Lib\site-packages\rest_framework\serializers.py", line 235, in is_valid
    raise ValidationError(self.errors)
rest_framework.exceptions.ValidationError: {'collaborator': [ErrorDetail(string='This field is required.', code='required')]}
03/04/2023 10:36:08 AM : logging_confiq.logger : 
Traceback (most recent call last):
  File "C:\Users\RJ EMPIRE\Desktop\Django\FundooNotes\Notes\views.py", line 28, in post
    serializer.is_valid(raise_exception=True)
  File "C:\Users\RJ EMPIRE\Desktop\env\env03\Lib\site-packages\rest_framework\serializers.py", line 235, in is_valid
    raise ValidationError(self.errors)
rest_framework.exceptions.ValidationError: {'collaborator': [ErrorDetail(string='This field is required.', code='required')]}
03/04/2023 10:36:08 AM : logging_confiq.logger : 
Traceback (most recent call last):
  File "C:\Users\RJ EMPIRE\Desktop\Django\FundooNotes\Notes\views.py", line 28, in post
    serializer.is_valid(raise_exception=True)
  File "C:\Users\RJ EMPIRE\Desktop\env\env03\Lib\site-packages\rest_framework\serializers.py", line 235, in is_valid
    raise ValidationError(self.errors)
rest_framework.exceptions.ValidationError: {'collaborator': [ErrorDetail(string='This field is required.', code='required')]}
03/04/2023 10:36:08 AM : logging_confiq.logger : 
Traceback (most recent call last):
  File "C:\Users\RJ EMPIRE\Desktop\Django\FundooNotes\Notes\views.py", line 28, in post
    serializer.is_valid(raise_exception=True)
  File "C:\Users\RJ EMPIRE\Desktop\env\env03\Lib\site-packages\rest_framework\serializers.py", line 235, in is_valid
    raise ValidationError(self.errors)
rest_framework.exceptions.ValidationError: {'collaborator': [ErrorDetail(string='This field is required.', code='required')]}
03/04/2023 10:36:09 AM : logging_confiq.logger : 
Traceback (most recent call last):
  File "C:\Users\RJ EMPIRE\Desktop\Django\FundooNotes\user_auth\views.py", line 87, in post
    serializer.save()
  File "C:\Users\RJ EMPIRE\Desktop\env\env03\Lib\site-packages\rest_framework\serializers.py", line 212, in save
    self.instance = self.create(validated_data)
                    ^^^^^^^^^^^^^^^^^^^^^^^^^^^
  File "C:\Users\RJ EMPIRE\Desktop\Django\FundooNotes\user_auth\serializers.py", line 32, in create
    raise serializers.ValidationError("Incorrect Credentials")
rest_framework.exceptions.ValidationError: [ErrorDetail(string='Incorrect Credentials', code='invalid')]
03/04/2023 10:36:09 AM : logging_confiq.logger : 
Traceback (most recent call last):
  File "C:\Users\RJ EMPIRE\Desktop\Django\FundooNotes\user_auth\views.py", line 87, in post
    serializer.save()
  File "C:\Users\RJ EMPIRE\Desktop\env\env03\Lib\site-packages\rest_framework\serializers.py", line 212, in save
    self.instance = self.create(validated_data)
                    ^^^^^^^^^^^^^^^^^^^^^^^^^^^
  File "C:\Users\RJ EMPIRE\Desktop\Django\FundooNotes\user_auth\serializers.py", line 32, in create
    raise serializers.ValidationError("Incorrect Credentials")
rest_framework.exceptions.ValidationError: [ErrorDetail(string='Incorrect Credentials', code='invalid')]
03/04/2023 10:36:09 AM : logging_confiq.logger : 
Traceback (most recent call last):
  File "C:\Users\RJ EMPIRE\Desktop\Django\FundooNotes\user_auth\views.py", line 85, in post
    serializer.is_valid(raise_exception=True)
  File "C:\Users\RJ EMPIRE\Desktop\env\env03\Lib\site-packages\rest_framework\serializers.py", line 235, in is_valid
    raise ValidationError(self.errors)
rest_framework.exceptions.ValidationError: {'password': [ErrorDetail(string='This field is required.', code='required')]}
03/04/2023 10:36:09 AM : logging_confiq.logger : 
Traceback (most recent call last):
  File "C:\Users\RJ EMPIRE\Desktop\Django\FundooNotes\user_auth\views.py", line 85, in post
    serializer.is_valid(raise_exception=True)
  File "C:\Users\RJ EMPIRE\Desktop\env\env03\Lib\site-packages\rest_framework\serializers.py", line 235, in is_valid
    raise ValidationError(self.errors)
rest_framework.exceptions.ValidationError: {'password': [ErrorDetail(string='This field is required.', code='required')]}
03/04/2023 10:36:10 AM : logging_confiq.logger : 
Traceback (most recent call last):
  File "C:\Users\RJ EMPIRE\Desktop\Django\FundooNotes\user_auth\views.py", line 28, in post
    serializer.is_valid(raise_exception=True)
  File "C:\Users\RJ EMPIRE\Desktop\env\env03\Lib\site-packages\rest_framework\serializers.py", line 235, in is_valid
    raise ValidationError(self.errors)
rest_framework.exceptions.ValidationError: {'address': [ErrorDetail(string='This field is required.', code='required')], 'username': [ErrorDetail(string='This field is required.', code='required')], 'password': [ErrorDetail(string='This field is required.', code='required')]}
03/04/2023 10:36:10 AM : logging_confiq.logger : 
Traceback (most recent call last):
  File "C:\Users\RJ EMPIRE\Desktop\Django\FundooNotes\user_auth\views.py", line 28, in post
    serializer.is_valid(raise_exception=True)
  File "C:\Users\RJ EMPIRE\Desktop\env\env03\Lib\site-packages\rest_framework\serializers.py", line 235, in is_valid
    raise ValidationError(self.errors)
rest_framework.exceptions.ValidationError: {'address': [ErrorDetail(string='This field is required.', code='required')], 'username': [ErrorDetail(string='This field is required.', code='required')], 'password': [ErrorDetail(string='This field is required.', code='required')]}
03/04/2023 10:36:11 AM : logging_confiq.logger : 
Traceback (most recent call last):
  File "C:\Users\RJ EMPIRE\Desktop\Django\FundooNotes\user_auth\views.py", line 28, in post
    serializer.is_valid(raise_exception=True)
  File "C:\Users\RJ EMPIRE\Desktop\env\env03\Lib\site-packages\rest_framework\serializers.py", line 235, in is_valid
    raise ValidationError(self.errors)
rest_framework.exceptions.ValidationError: {'username': [ErrorDetail(string='This field may not be blank.', code='blank')]}
03/04/2023 10:36:11 AM : logging_confiq.logger : 
Traceback (most recent call last):
  File "C:\Users\RJ EMPIRE\Desktop\Django\FundooNotes\user_auth\views.py", line 28, in post
    serializer.is_valid(raise_exception=True)
  File "C:\Users\RJ EMPIRE\Desktop\env\env03\Lib\site-packages\rest_framework\serializers.py", line 235, in is_valid
    raise ValidationError(self.errors)
rest_framework.exceptions.ValidationError: {'username': [ErrorDetail(string='This field may not be blank.', code='blank')]}
03/05/2023 10:50:36 AM : logging_confiq.logger : 
Traceback (most recent call last):
  File "C:\Users\RJ EMPIRE\Desktop\Django\FundooNotes\Notes\views.py", line 28, in post
    serializer.is_valid(raise_exception=True)
  File "C:\Users\RJ EMPIRE\Desktop\env\env03\Lib\site-packages\rest_framework\serializers.py", line 235, in is_valid
    raise ValidationError(self.errors)
rest_framework.exceptions.ValidationError: {'title': [ErrorDetail(string='This field is required.', code='required')], 'collaborator': [ErrorDetail(string='This field is required.', code='required')]}
03/05/2023 10:50:36 AM : logging_confiq.logger : 
Traceback (most recent call last):
  File "C:\Users\RJ EMPIRE\Desktop\Django\FundooNotes\Notes\views.py", line 28, in post
    serializer.is_valid(raise_exception=True)
  File "C:\Users\RJ EMPIRE\Desktop\env\env03\Lib\site-packages\rest_framework\serializers.py", line 235, in is_valid
    raise ValidationError(self.errors)
rest_framework.exceptions.ValidationError: {'title': [ErrorDetail(string='This field is required.', code='required')], 'collaborator': [ErrorDetail(string='This field is required.', code='required')]}
03/05/2023 10:50:36 AM : logging_confiq.logger : 
Traceback (most recent call last):
  File "C:\Users\RJ EMPIRE\Desktop\Django\FundooNotes\Notes\views.py", line 28, in post
    serializer.is_valid(raise_exception=True)
  File "C:\Users\RJ EMPIRE\Desktop\env\env03\Lib\site-packages\rest_framework\serializers.py", line 235, in is_valid
    raise ValidationError(self.errors)
rest_framework.exceptions.ValidationError: {'collaborator': [ErrorDetail(string='This field is required.', code='required')]}
03/05/2023 10:50:36 AM : logging_confiq.logger : 
Traceback (most recent call last):
  File "C:\Users\RJ EMPIRE\Desktop\Django\FundooNotes\Notes\views.py", line 28, in post
    serializer.is_valid(raise_exception=True)
  File "C:\Users\RJ EMPIRE\Desktop\env\env03\Lib\site-packages\rest_framework\serializers.py", line 235, in is_valid
    raise ValidationError(self.errors)
rest_framework.exceptions.ValidationError: {'collaborator': [ErrorDetail(string='This field is required.', code='required')]}
03/05/2023 10:50:37 AM : logging_confiq.logger : 
Traceback (most recent call last):
  File "C:\Users\RJ EMPIRE\Desktop\Django\FundooNotes\Notes\views.py", line 28, in post
    serializer.is_valid(raise_exception=True)
  File "C:\Users\RJ EMPIRE\Desktop\env\env03\Lib\site-packages\rest_framework\serializers.py", line 235, in is_valid
    raise ValidationError(self.errors)
rest_framework.exceptions.ValidationError: {'collaborator': [ErrorDetail(string='This field is required.', code='required')]}
03/05/2023 10:50:37 AM : logging_confiq.logger : 
Traceback (most recent call last):
  File "C:\Users\RJ EMPIRE\Desktop\Django\FundooNotes\Notes\views.py", line 28, in post
    serializer.is_valid(raise_exception=True)
  File "C:\Users\RJ EMPIRE\Desktop\env\env03\Lib\site-packages\rest_framework\serializers.py", line 235, in is_valid
    raise ValidationError(self.errors)
rest_framework.exceptions.ValidationError: {'collaborator': [ErrorDetail(string='This field is required.', code='required')]}
03/05/2023 10:50:40 AM : logging_confiq.logger : 
Traceback (most recent call last):
  File "C:\Users\RJ EMPIRE\Desktop\Django\FundooNotes\Notes\views.py", line 28, in post
    serializer.is_valid(raise_exception=True)
  File "C:\Users\RJ EMPIRE\Desktop\env\env03\Lib\site-packages\rest_framework\serializers.py", line 235, in is_valid
    raise ValidationError(self.errors)
rest_framework.exceptions.ValidationError: {'collaborator': [ErrorDetail(string='This field is required.', code='required')]}
03/05/2023 10:50:40 AM : logging_confiq.logger : 
Traceback (most recent call last):
  File "C:\Users\RJ EMPIRE\Desktop\Django\FundooNotes\Notes\views.py", line 28, in post
    serializer.is_valid(raise_exception=True)
  File "C:\Users\RJ EMPIRE\Desktop\env\env03\Lib\site-packages\rest_framework\serializers.py", line 235, in is_valid
    raise ValidationError(self.errors)
rest_framework.exceptions.ValidationError: {'collaborator': [ErrorDetail(string='This field is required.', code='required')]}
03/05/2023 10:50:40 AM : logging_confiq.logger : 
Traceback (most recent call last):
  File "C:\Users\RJ EMPIRE\Desktop\Django\FundooNotes\Notes\views.py", line 28, in post
    serializer.is_valid(raise_exception=True)
  File "C:\Users\RJ EMPIRE\Desktop\env\env03\Lib\site-packages\rest_framework\serializers.py", line 235, in is_valid
    raise ValidationError(self.errors)
rest_framework.exceptions.ValidationError: {'collaborator': [ErrorDetail(string='This field is required.', code='required')]}
03/05/2023 10:50:40 AM : logging_confiq.logger : 
Traceback (most recent call last):
  File "C:\Users\RJ EMPIRE\Desktop\Django\FundooNotes\Notes\views.py", line 28, in post
    serializer.is_valid(raise_exception=True)
  File "C:\Users\RJ EMPIRE\Desktop\env\env03\Lib\site-packages\rest_framework\serializers.py", line 235, in is_valid
    raise ValidationError(self.errors)
rest_framework.exceptions.ValidationError: {'collaborator': [ErrorDetail(string='This field is required.', code='required')]}
03/05/2023 10:50:41 AM : logging_confiq.logger : 
Traceback (most recent call last):
  File "C:\Users\RJ EMPIRE\Desktop\Django\FundooNotes\user_auth\views.py", line 87, in post
    serializer.save()
  File "C:\Users\RJ EMPIRE\Desktop\env\env03\Lib\site-packages\rest_framework\serializers.py", line 212, in save
    self.instance = self.create(validated_data)
                    ^^^^^^^^^^^^^^^^^^^^^^^^^^^
  File "C:\Users\RJ EMPIRE\Desktop\Django\FundooNotes\user_auth\serializers.py", line 32, in create
    raise serializers.ValidationError("Incorrect Credentials")
rest_framework.exceptions.ValidationError: [ErrorDetail(string='Incorrect Credentials', code='invalid')]
03/05/2023 10:50:41 AM : logging_confiq.logger : 
Traceback (most recent call last):
  File "C:\Users\RJ EMPIRE\Desktop\Django\FundooNotes\user_auth\views.py", line 87, in post
    serializer.save()
  File "C:\Users\RJ EMPIRE\Desktop\env\env03\Lib\site-packages\rest_framework\serializers.py", line 212, in save
    self.instance = self.create(validated_data)
                    ^^^^^^^^^^^^^^^^^^^^^^^^^^^
  File "C:\Users\RJ EMPIRE\Desktop\Django\FundooNotes\user_auth\serializers.py", line 32, in create
    raise serializers.ValidationError("Incorrect Credentials")
rest_framework.exceptions.ValidationError: [ErrorDetail(string='Incorrect Credentials', code='invalid')]
03/05/2023 10:50:41 AM : logging_confiq.logger : 
Traceback (most recent call last):
  File "C:\Users\RJ EMPIRE\Desktop\Django\FundooNotes\user_auth\views.py", line 85, in post
    serializer.is_valid(raise_exception=True)
  File "C:\Users\RJ EMPIRE\Desktop\env\env03\Lib\site-packages\rest_framework\serializers.py", line 235, in is_valid
    raise ValidationError(self.errors)
rest_framework.exceptions.ValidationError: {'password': [ErrorDetail(string='This field is required.', code='required')]}
03/05/2023 10:50:41 AM : logging_confiq.logger : 
Traceback (most recent call last):
  File "C:\Users\RJ EMPIRE\Desktop\Django\FundooNotes\user_auth\views.py", line 85, in post
    serializer.is_valid(raise_exception=True)
  File "C:\Users\RJ EMPIRE\Desktop\env\env03\Lib\site-packages\rest_framework\serializers.py", line 235, in is_valid
    raise ValidationError(self.errors)
rest_framework.exceptions.ValidationError: {'password': [ErrorDetail(string='This field is required.', code='required')]}
03/05/2023 10:50:42 AM : logging_confiq.logger : 
Traceback (most recent call last):
  File "C:\Users\RJ EMPIRE\Desktop\Django\FundooNotes\user_auth\views.py", line 28, in post
    serializer.is_valid(raise_exception=True)
  File "C:\Users\RJ EMPIRE\Desktop\env\env03\Lib\site-packages\rest_framework\serializers.py", line 235, in is_valid
    raise ValidationError(self.errors)
rest_framework.exceptions.ValidationError: {'address': [ErrorDetail(string='This field is required.', code='required')], 'username': [ErrorDetail(string='This field is required.', code='required')], 'password': [ErrorDetail(string='This field is required.', code='required')]}
03/05/2023 10:50:42 AM : logging_confiq.logger : 
Traceback (most recent call last):
  File "C:\Users\RJ EMPIRE\Desktop\Django\FundooNotes\user_auth\views.py", line 28, in post
    serializer.is_valid(raise_exception=True)
  File "C:\Users\RJ EMPIRE\Desktop\env\env03\Lib\site-packages\rest_framework\serializers.py", line 235, in is_valid
    raise ValidationError(self.errors)
rest_framework.exceptions.ValidationError: {'address': [ErrorDetail(string='This field is required.', code='required')], 'username': [ErrorDetail(string='This field is required.', code='required')], 'password': [ErrorDetail(string='This field is required.', code='required')]}
03/05/2023 10:50:43 AM : logging_confiq.logger : 
Traceback (most recent call last):
  File "C:\Users\RJ EMPIRE\Desktop\Django\FundooNotes\user_auth\views.py", line 28, in post
    serializer.is_valid(raise_exception=True)
  File "C:\Users\RJ EMPIRE\Desktop\env\env03\Lib\site-packages\rest_framework\serializers.py", line 235, in is_valid
    raise ValidationError(self.errors)
rest_framework.exceptions.ValidationError: {'username': [ErrorDetail(string='This field may not be blank.', code='blank')]}
03/05/2023 10:50:43 AM : logging_confiq.logger : 
Traceback (most recent call last):
  File "C:\Users\RJ EMPIRE\Desktop\Django\FundooNotes\user_auth\views.py", line 28, in post
    serializer.is_valid(raise_exception=True)
  File "C:\Users\RJ EMPIRE\Desktop\env\env03\Lib\site-packages\rest_framework\serializers.py", line 235, in is_valid
    raise ValidationError(self.errors)
rest_framework.exceptions.ValidationError: {'username': [ErrorDetail(string='This field may not be blank.', code='blank')]}
03/05/2023 10:52:07 AM : logging_confiq.logger : 
Traceback (most recent call last):
  File "C:\Users\RJ EMPIRE\Desktop\Django\FundooNotes\Notes\views.py", line 28, in post
    serializer.is_valid(raise_exception=True)
  File "C:\Users\RJ EMPIRE\Desktop\env\env03\Lib\site-packages\rest_framework\serializers.py", line 235, in is_valid
    raise ValidationError(self.errors)
rest_framework.exceptions.ValidationError: {'title': [ErrorDetail(string='This field is required.', code='required')], 'collaborator': [ErrorDetail(string='This field is required.', code='required')]}
03/05/2023 10:52:07 AM : logging_confiq.logger : 
Traceback (most recent call last):
  File "C:\Users\RJ EMPIRE\Desktop\Django\FundooNotes\Notes\views.py", line 28, in post
    serializer.is_valid(raise_exception=True)
  File "C:\Users\RJ EMPIRE\Desktop\env\env03\Lib\site-packages\rest_framework\serializers.py", line 235, in is_valid
    raise ValidationError(self.errors)
rest_framework.exceptions.ValidationError: {'title': [ErrorDetail(string='This field is required.', code='required')], 'collaborator': [ErrorDetail(string='This field is required.', code='required')]}
03/05/2023 10:52:07 AM : logging_confiq.logger : 
Traceback (most recent call last):
  File "C:\Users\RJ EMPIRE\Desktop\Django\FundooNotes\Notes\views.py", line 28, in post
    serializer.is_valid(raise_exception=True)
  File "C:\Users\RJ EMPIRE\Desktop\env\env03\Lib\site-packages\rest_framework\serializers.py", line 235, in is_valid
    raise ValidationError(self.errors)
rest_framework.exceptions.ValidationError: {'collaborator': [ErrorDetail(string='This field is required.', code='required')]}
03/05/2023 10:52:07 AM : logging_confiq.logger : 
Traceback (most recent call last):
  File "C:\Users\RJ EMPIRE\Desktop\Django\FundooNotes\Notes\views.py", line 28, in post
    serializer.is_valid(raise_exception=True)
  File "C:\Users\RJ EMPIRE\Desktop\env\env03\Lib\site-packages\rest_framework\serializers.py", line 235, in is_valid
    raise ValidationError(self.errors)
rest_framework.exceptions.ValidationError: {'collaborator': [ErrorDetail(string='This field is required.', code='required')]}
03/05/2023 10:52:08 AM : logging_confiq.logger : 
Traceback (most recent call last):
  File "C:\Users\RJ EMPIRE\Desktop\Django\FundooNotes\Notes\views.py", line 28, in post
    serializer.is_valid(raise_exception=True)
  File "C:\Users\RJ EMPIRE\Desktop\env\env03\Lib\site-packages\rest_framework\serializers.py", line 235, in is_valid
    raise ValidationError(self.errors)
rest_framework.exceptions.ValidationError: {'collaborator': [ErrorDetail(string='This field is required.', code='required')]}
03/05/2023 10:52:08 AM : logging_confiq.logger : 
Traceback (most recent call last):
  File "C:\Users\RJ EMPIRE\Desktop\Django\FundooNotes\Notes\views.py", line 28, in post
    serializer.is_valid(raise_exception=True)
  File "C:\Users\RJ EMPIRE\Desktop\env\env03\Lib\site-packages\rest_framework\serializers.py", line 235, in is_valid
    raise ValidationError(self.errors)
rest_framework.exceptions.ValidationError: {'collaborator': [ErrorDetail(string='This field is required.', code='required')]}
03/05/2023 10:52:11 AM : logging_confiq.logger : 
Traceback (most recent call last):
  File "C:\Users\RJ EMPIRE\Desktop\Django\FundooNotes\Notes\views.py", line 28, in post
    serializer.is_valid(raise_exception=True)
  File "C:\Users\RJ EMPIRE\Desktop\env\env03\Lib\site-packages\rest_framework\serializers.py", line 235, in is_valid
    raise ValidationError(self.errors)
rest_framework.exceptions.ValidationError: {'collaborator': [ErrorDetail(string='This field is required.', code='required')]}
03/05/2023 10:52:11 AM : logging_confiq.logger : 
Traceback (most recent call last):
  File "C:\Users\RJ EMPIRE\Desktop\Django\FundooNotes\Notes\views.py", line 28, in post
    serializer.is_valid(raise_exception=True)
  File "C:\Users\RJ EMPIRE\Desktop\env\env03\Lib\site-packages\rest_framework\serializers.py", line 235, in is_valid
    raise ValidationError(self.errors)
rest_framework.exceptions.ValidationError: {'collaborator': [ErrorDetail(string='This field is required.', code='required')]}
03/05/2023 10:52:12 AM : logging_confiq.logger : 
Traceback (most recent call last):
  File "C:\Users\RJ EMPIRE\Desktop\Django\FundooNotes\Notes\views.py", line 28, in post
    serializer.is_valid(raise_exception=True)
  File "C:\Users\RJ EMPIRE\Desktop\env\env03\Lib\site-packages\rest_framework\serializers.py", line 235, in is_valid
    raise ValidationError(self.errors)
rest_framework.exceptions.ValidationError: {'collaborator': [ErrorDetail(string='This field is required.', code='required')]}
03/05/2023 10:52:12 AM : logging_confiq.logger : 
Traceback (most recent call last):
  File "C:\Users\RJ EMPIRE\Desktop\Django\FundooNotes\Notes\views.py", line 28, in post
    serializer.is_valid(raise_exception=True)
  File "C:\Users\RJ EMPIRE\Desktop\env\env03\Lib\site-packages\rest_framework\serializers.py", line 235, in is_valid
    raise ValidationError(self.errors)
rest_framework.exceptions.ValidationError: {'collaborator': [ErrorDetail(string='This field is required.', code='required')]}
03/05/2023 10:52:12 AM : logging_confiq.logger : 
Traceback (most recent call last):
  File "C:\Users\RJ EMPIRE\Desktop\Django\FundooNotes\user_auth\views.py", line 87, in post
    serializer.save()
  File "C:\Users\RJ EMPIRE\Desktop\env\env03\Lib\site-packages\rest_framework\serializers.py", line 212, in save
    self.instance = self.create(validated_data)
                    ^^^^^^^^^^^^^^^^^^^^^^^^^^^
  File "C:\Users\RJ EMPIRE\Desktop\Django\FundooNotes\user_auth\serializers.py", line 32, in create
    raise serializers.ValidationError("Incorrect Credentials")
rest_framework.exceptions.ValidationError: [ErrorDetail(string='Incorrect Credentials', code='invalid')]
03/05/2023 10:52:12 AM : logging_confiq.logger : 
Traceback (most recent call last):
  File "C:\Users\RJ EMPIRE\Desktop\Django\FundooNotes\user_auth\views.py", line 87, in post
    serializer.save()
  File "C:\Users\RJ EMPIRE\Desktop\env\env03\Lib\site-packages\rest_framework\serializers.py", line 212, in save
    self.instance = self.create(validated_data)
                    ^^^^^^^^^^^^^^^^^^^^^^^^^^^
  File "C:\Users\RJ EMPIRE\Desktop\Django\FundooNotes\user_auth\serializers.py", line 32, in create
    raise serializers.ValidationError("Incorrect Credentials")
rest_framework.exceptions.ValidationError: [ErrorDetail(string='Incorrect Credentials', code='invalid')]
03/05/2023 10:52:12 AM : logging_confiq.logger : 
Traceback (most recent call last):
  File "C:\Users\RJ EMPIRE\Desktop\Django\FundooNotes\user_auth\views.py", line 85, in post
    serializer.is_valid(raise_exception=True)
  File "C:\Users\RJ EMPIRE\Desktop\env\env03\Lib\site-packages\rest_framework\serializers.py", line 235, in is_valid
    raise ValidationError(self.errors)
rest_framework.exceptions.ValidationError: {'password': [ErrorDetail(string='This field is required.', code='required')]}
03/05/2023 10:52:12 AM : logging_confiq.logger : 
Traceback (most recent call last):
  File "C:\Users\RJ EMPIRE\Desktop\Django\FundooNotes\user_auth\views.py", line 85, in post
    serializer.is_valid(raise_exception=True)
  File "C:\Users\RJ EMPIRE\Desktop\env\env03\Lib\site-packages\rest_framework\serializers.py", line 235, in is_valid
    raise ValidationError(self.errors)
rest_framework.exceptions.ValidationError: {'password': [ErrorDetail(string='This field is required.', code='required')]}
03/05/2023 10:52:13 AM : logging_confiq.logger : 
Traceback (most recent call last):
  File "C:\Users\RJ EMPIRE\Desktop\Django\FundooNotes\user_auth\views.py", line 28, in post
    serializer.is_valid(raise_exception=True)
  File "C:\Users\RJ EMPIRE\Desktop\env\env03\Lib\site-packages\rest_framework\serializers.py", line 235, in is_valid
    raise ValidationError(self.errors)
rest_framework.exceptions.ValidationError: {'address': [ErrorDetail(string='This field is required.', code='required')], 'username': [ErrorDetail(string='This field is required.', code='required')], 'password': [ErrorDetail(string='This field is required.', code='required')]}
03/05/2023 10:52:13 AM : logging_confiq.logger : 
Traceback (most recent call last):
  File "C:\Users\RJ EMPIRE\Desktop\Django\FundooNotes\user_auth\views.py", line 28, in post
    serializer.is_valid(raise_exception=True)
  File "C:\Users\RJ EMPIRE\Desktop\env\env03\Lib\site-packages\rest_framework\serializers.py", line 235, in is_valid
    raise ValidationError(self.errors)
rest_framework.exceptions.ValidationError: {'address': [ErrorDetail(string='This field is required.', code='required')], 'username': [ErrorDetail(string='This field is required.', code='required')], 'password': [ErrorDetail(string='This field is required.', code='required')]}
03/05/2023 10:52:14 AM : logging_confiq.logger : 
Traceback (most recent call last):
  File "C:\Users\RJ EMPIRE\Desktop\Django\FundooNotes\user_auth\views.py", line 28, in post
    serializer.is_valid(raise_exception=True)
  File "C:\Users\RJ EMPIRE\Desktop\env\env03\Lib\site-packages\rest_framework\serializers.py", line 235, in is_valid
    raise ValidationError(self.errors)
rest_framework.exceptions.ValidationError: {'username': [ErrorDetail(string='This field may not be blank.', code='blank')]}
03/05/2023 10:52:14 AM : logging_confiq.logger : 
Traceback (most recent call last):
  File "C:\Users\RJ EMPIRE\Desktop\Django\FundooNotes\user_auth\views.py", line 28, in post
    serializer.is_valid(raise_exception=True)
  File "C:\Users\RJ EMPIRE\Desktop\env\env03\Lib\site-packages\rest_framework\serializers.py", line 235, in is_valid
    raise ValidationError(self.errors)
rest_framework.exceptions.ValidationError: {'username': [ErrorDetail(string='This field may not be blank.', code='blank')]}
03/05/2023 10:55:00 AM : logging_confiq.logger : 
Traceback (most recent call last):
  File "C:\Users\RJ EMPIRE\Desktop\Django\FundooNotes\Notes\views.py", line 28, in post
    serializer.is_valid(raise_exception=True)
  File "C:\Users\RJ EMPIRE\Desktop\env\env03\Lib\site-packages\rest_framework\serializers.py", line 235, in is_valid
    raise ValidationError(self.errors)
rest_framework.exceptions.ValidationError: {'title': [ErrorDetail(string='This field is required.', code='required')], 'collaborator': [ErrorDetail(string='This field is required.', code='required')]}
03/05/2023 10:55:00 AM : logging_confiq.logger : 
Traceback (most recent call last):
  File "C:\Users\RJ EMPIRE\Desktop\Django\FundooNotes\Notes\views.py", line 28, in post
    serializer.is_valid(raise_exception=True)
  File "C:\Users\RJ EMPIRE\Desktop\env\env03\Lib\site-packages\rest_framework\serializers.py", line 235, in is_valid
    raise ValidationError(self.errors)
rest_framework.exceptions.ValidationError: {'title': [ErrorDetail(string='This field is required.', code='required')], 'collaborator': [ErrorDetail(string='This field is required.', code='required')]}
03/05/2023 10:55:00 AM : logging_confiq.logger : 
Traceback (most recent call last):
  File "C:\Users\RJ EMPIRE\Desktop\Django\FundooNotes\Notes\views.py", line 28, in post
    serializer.is_valid(raise_exception=True)
  File "C:\Users\RJ EMPIRE\Desktop\env\env03\Lib\site-packages\rest_framework\serializers.py", line 235, in is_valid
    raise ValidationError(self.errors)
rest_framework.exceptions.ValidationError: {'collaborator': [ErrorDetail(string='This field is required.', code='required')]}
03/05/2023 10:55:00 AM : logging_confiq.logger : 
Traceback (most recent call last):
  File "C:\Users\RJ EMPIRE\Desktop\Django\FundooNotes\Notes\views.py", line 28, in post
    serializer.is_valid(raise_exception=True)
  File "C:\Users\RJ EMPIRE\Desktop\env\env03\Lib\site-packages\rest_framework\serializers.py", line 235, in is_valid
    raise ValidationError(self.errors)
rest_framework.exceptions.ValidationError: {'collaborator': [ErrorDetail(string='This field is required.', code='required')]}
03/05/2023 10:55:01 AM : logging_confiq.logger : 
Traceback (most recent call last):
  File "C:\Users\RJ EMPIRE\Desktop\Django\FundooNotes\Notes\views.py", line 28, in post
    serializer.is_valid(raise_exception=True)
  File "C:\Users\RJ EMPIRE\Desktop\env\env03\Lib\site-packages\rest_framework\serializers.py", line 235, in is_valid
    raise ValidationError(self.errors)
rest_framework.exceptions.ValidationError: {'collaborator': [ErrorDetail(string='This field is required.', code='required')]}
03/05/2023 10:55:01 AM : logging_confiq.logger : 
Traceback (most recent call last):
  File "C:\Users\RJ EMPIRE\Desktop\Django\FundooNotes\Notes\views.py", line 28, in post
    serializer.is_valid(raise_exception=True)
  File "C:\Users\RJ EMPIRE\Desktop\env\env03\Lib\site-packages\rest_framework\serializers.py", line 235, in is_valid
    raise ValidationError(self.errors)
rest_framework.exceptions.ValidationError: {'collaborator': [ErrorDetail(string='This field is required.', code='required')]}
03/05/2023 10:55:04 AM : logging_confiq.logger : 
Traceback (most recent call last):
  File "C:\Users\RJ EMPIRE\Desktop\Django\FundooNotes\Notes\views.py", line 28, in post
    serializer.is_valid(raise_exception=True)
  File "C:\Users\RJ EMPIRE\Desktop\env\env03\Lib\site-packages\rest_framework\serializers.py", line 235, in is_valid
    raise ValidationError(self.errors)
rest_framework.exceptions.ValidationError: {'collaborator': [ErrorDetail(string='This field is required.', code='required')]}
03/05/2023 10:55:04 AM : logging_confiq.logger : 
Traceback (most recent call last):
  File "C:\Users\RJ EMPIRE\Desktop\Django\FundooNotes\Notes\views.py", line 28, in post
    serializer.is_valid(raise_exception=True)
  File "C:\Users\RJ EMPIRE\Desktop\env\env03\Lib\site-packages\rest_framework\serializers.py", line 235, in is_valid
    raise ValidationError(self.errors)
rest_framework.exceptions.ValidationError: {'collaborator': [ErrorDetail(string='This field is required.', code='required')]}
03/05/2023 10:55:04 AM : logging_confiq.logger : 
Traceback (most recent call last):
  File "C:\Users\RJ EMPIRE\Desktop\Django\FundooNotes\Notes\views.py", line 28, in post
    serializer.is_valid(raise_exception=True)
  File "C:\Users\RJ EMPIRE\Desktop\env\env03\Lib\site-packages\rest_framework\serializers.py", line 235, in is_valid
    raise ValidationError(self.errors)
rest_framework.exceptions.ValidationError: {'collaborator': [ErrorDetail(string='This field is required.', code='required')]}
03/05/2023 10:55:04 AM : logging_confiq.logger : 
Traceback (most recent call last):
  File "C:\Users\RJ EMPIRE\Desktop\Django\FundooNotes\Notes\views.py", line 28, in post
    serializer.is_valid(raise_exception=True)
  File "C:\Users\RJ EMPIRE\Desktop\env\env03\Lib\site-packages\rest_framework\serializers.py", line 235, in is_valid
    raise ValidationError(self.errors)
rest_framework.exceptions.ValidationError: {'collaborator': [ErrorDetail(string='This field is required.', code='required')]}
03/05/2023 10:55:05 AM : logging_confiq.logger : 
Traceback (most recent call last):
  File "C:\Users\RJ EMPIRE\Desktop\Django\FundooNotes\user_auth\views.py", line 87, in post
    serializer.save()
  File "C:\Users\RJ EMPIRE\Desktop\env\env03\Lib\site-packages\rest_framework\serializers.py", line 212, in save
    self.instance = self.create(validated_data)
                    ^^^^^^^^^^^^^^^^^^^^^^^^^^^
  File "C:\Users\RJ EMPIRE\Desktop\Django\FundooNotes\user_auth\serializers.py", line 32, in create
    raise serializers.ValidationError("Incorrect Credentials")
rest_framework.exceptions.ValidationError: [ErrorDetail(string='Incorrect Credentials', code='invalid')]
03/05/2023 10:55:05 AM : logging_confiq.logger : 
Traceback (most recent call last):
  File "C:\Users\RJ EMPIRE\Desktop\Django\FundooNotes\user_auth\views.py", line 87, in post
    serializer.save()
  File "C:\Users\RJ EMPIRE\Desktop\env\env03\Lib\site-packages\rest_framework\serializers.py", line 212, in save
    self.instance = self.create(validated_data)
                    ^^^^^^^^^^^^^^^^^^^^^^^^^^^
  File "C:\Users\RJ EMPIRE\Desktop\Django\FundooNotes\user_auth\serializers.py", line 32, in create
    raise serializers.ValidationError("Incorrect Credentials")
rest_framework.exceptions.ValidationError: [ErrorDetail(string='Incorrect Credentials', code='invalid')]
03/05/2023 10:55:05 AM : logging_confiq.logger : 
Traceback (most recent call last):
  File "C:\Users\RJ EMPIRE\Desktop\Django\FundooNotes\user_auth\views.py", line 85, in post
    serializer.is_valid(raise_exception=True)
  File "C:\Users\RJ EMPIRE\Desktop\env\env03\Lib\site-packages\rest_framework\serializers.py", line 235, in is_valid
    raise ValidationError(self.errors)
rest_framework.exceptions.ValidationError: {'password': [ErrorDetail(string='This field is required.', code='required')]}
03/05/2023 10:55:05 AM : logging_confiq.logger : 
Traceback (most recent call last):
  File "C:\Users\RJ EMPIRE\Desktop\Django\FundooNotes\user_auth\views.py", line 85, in post
    serializer.is_valid(raise_exception=True)
  File "C:\Users\RJ EMPIRE\Desktop\env\env03\Lib\site-packages\rest_framework\serializers.py", line 235, in is_valid
    raise ValidationError(self.errors)
rest_framework.exceptions.ValidationError: {'password': [ErrorDetail(string='This field is required.', code='required')]}
03/05/2023 10:55:06 AM : logging_confiq.logger : 
Traceback (most recent call last):
  File "C:\Users\RJ EMPIRE\Desktop\Django\FundooNotes\user_auth\views.py", line 28, in post
    serializer.is_valid(raise_exception=True)
  File "C:\Users\RJ EMPIRE\Desktop\env\env03\Lib\site-packages\rest_framework\serializers.py", line 235, in is_valid
    raise ValidationError(self.errors)
rest_framework.exceptions.ValidationError: {'address': [ErrorDetail(string='This field is required.', code='required')], 'username': [ErrorDetail(string='This field is required.', code='required')], 'password': [ErrorDetail(string='This field is required.', code='required')]}
03/05/2023 10:55:06 AM : logging_confiq.logger : 
Traceback (most recent call last):
  File "C:\Users\RJ EMPIRE\Desktop\Django\FundooNotes\user_auth\views.py", line 28, in post
    serializer.is_valid(raise_exception=True)
  File "C:\Users\RJ EMPIRE\Desktop\env\env03\Lib\site-packages\rest_framework\serializers.py", line 235, in is_valid
    raise ValidationError(self.errors)
rest_framework.exceptions.ValidationError: {'address': [ErrorDetail(string='This field is required.', code='required')], 'username': [ErrorDetail(string='This field is required.', code='required')], 'password': [ErrorDetail(string='This field is required.', code='required')]}
03/05/2023 10:55:07 AM : logging_confiq.logger : 
Traceback (most recent call last):
  File "C:\Users\RJ EMPIRE\Desktop\Django\FundooNotes\user_auth\views.py", line 28, in post
    serializer.is_valid(raise_exception=True)
  File "C:\Users\RJ EMPIRE\Desktop\env\env03\Lib\site-packages\rest_framework\serializers.py", line 235, in is_valid
    raise ValidationError(self.errors)
rest_framework.exceptions.ValidationError: {'username': [ErrorDetail(string='This field may not be blank.', code='blank')]}
03/05/2023 10:55:07 AM : logging_confiq.logger : 
Traceback (most recent call last):
  File "C:\Users\RJ EMPIRE\Desktop\Django\FundooNotes\user_auth\views.py", line 28, in post
    serializer.is_valid(raise_exception=True)
  File "C:\Users\RJ EMPIRE\Desktop\env\env03\Lib\site-packages\rest_framework\serializers.py", line 235, in is_valid
    raise ValidationError(self.errors)
rest_framework.exceptions.ValidationError: {'username': [ErrorDetail(string='This field may not be blank.', code='blank')]}
03/05/2023 10:56:23 AM : logging_confiq.logger : 
Traceback (most recent call last):
  File "C:\Users\RJ EMPIRE\Desktop\Django\FundooNotes\Notes\views.py", line 28, in post
    serializer.is_valid(raise_exception=True)
  File "C:\Users\RJ EMPIRE\Desktop\env\env03\Lib\site-packages\rest_framework\serializers.py", line 235, in is_valid
    raise ValidationError(self.errors)
rest_framework.exceptions.ValidationError: {'title': [ErrorDetail(string='This field is required.', code='required')]}
03/05/2023 10:56:23 AM : logging_confiq.logger : 
Traceback (most recent call last):
  File "C:\Users\RJ EMPIRE\Desktop\Django\FundooNotes\Notes\views.py", line 28, in post
    serializer.is_valid(raise_exception=True)
  File "C:\Users\RJ EMPIRE\Desktop\env\env03\Lib\site-packages\rest_framework\serializers.py", line 235, in is_valid
    raise ValidationError(self.errors)
rest_framework.exceptions.ValidationError: {'title': [ErrorDetail(string='This field is required.', code='required')]}
03/05/2023 10:56:29 AM : logging_confiq.logger : 
Traceback (most recent call last):
  File "C:\Users\RJ EMPIRE\Desktop\Django\FundooNotes\user_auth\views.py", line 87, in post
    serializer.save()
  File "C:\Users\RJ EMPIRE\Desktop\env\env03\Lib\site-packages\rest_framework\serializers.py", line 212, in save
    self.instance = self.create(validated_data)
                    ^^^^^^^^^^^^^^^^^^^^^^^^^^^
  File "C:\Users\RJ EMPIRE\Desktop\Django\FundooNotes\user_auth\serializers.py", line 32, in create
    raise serializers.ValidationError("Incorrect Credentials")
rest_framework.exceptions.ValidationError: [ErrorDetail(string='Incorrect Credentials', code='invalid')]
03/05/2023 10:56:29 AM : logging_confiq.logger : 
Traceback (most recent call last):
  File "C:\Users\RJ EMPIRE\Desktop\Django\FundooNotes\user_auth\views.py", line 87, in post
    serializer.save()
  File "C:\Users\RJ EMPIRE\Desktop\env\env03\Lib\site-packages\rest_framework\serializers.py", line 212, in save
    self.instance = self.create(validated_data)
                    ^^^^^^^^^^^^^^^^^^^^^^^^^^^
  File "C:\Users\RJ EMPIRE\Desktop\Django\FundooNotes\user_auth\serializers.py", line 32, in create
    raise serializers.ValidationError("Incorrect Credentials")
rest_framework.exceptions.ValidationError: [ErrorDetail(string='Incorrect Credentials', code='invalid')]
03/05/2023 10:56:29 AM : logging_confiq.logger : 
Traceback (most recent call last):
  File "C:\Users\RJ EMPIRE\Desktop\Django\FundooNotes\user_auth\views.py", line 85, in post
    serializer.is_valid(raise_exception=True)
  File "C:\Users\RJ EMPIRE\Desktop\env\env03\Lib\site-packages\rest_framework\serializers.py", line 235, in is_valid
    raise ValidationError(self.errors)
rest_framework.exceptions.ValidationError: {'password': [ErrorDetail(string='This field is required.', code='required')]}
03/05/2023 10:56:29 AM : logging_confiq.logger : 
Traceback (most recent call last):
  File "C:\Users\RJ EMPIRE\Desktop\Django\FundooNotes\user_auth\views.py", line 85, in post
    serializer.is_valid(raise_exception=True)
  File "C:\Users\RJ EMPIRE\Desktop\env\env03\Lib\site-packages\rest_framework\serializers.py", line 235, in is_valid
    raise ValidationError(self.errors)
rest_framework.exceptions.ValidationError: {'password': [ErrorDetail(string='This field is required.', code='required')]}
03/05/2023 10:56:30 AM : logging_confiq.logger : 
Traceback (most recent call last):
  File "C:\Users\RJ EMPIRE\Desktop\Django\FundooNotes\user_auth\views.py", line 28, in post
    serializer.is_valid(raise_exception=True)
  File "C:\Users\RJ EMPIRE\Desktop\env\env03\Lib\site-packages\rest_framework\serializers.py", line 235, in is_valid
    raise ValidationError(self.errors)
rest_framework.exceptions.ValidationError: {'address': [ErrorDetail(string='This field is required.', code='required')], 'username': [ErrorDetail(string='This field is required.', code='required')], 'password': [ErrorDetail(string='This field is required.', code='required')]}
03/05/2023 10:56:30 AM : logging_confiq.logger : 
Traceback (most recent call last):
  File "C:\Users\RJ EMPIRE\Desktop\Django\FundooNotes\user_auth\views.py", line 28, in post
    serializer.is_valid(raise_exception=True)
  File "C:\Users\RJ EMPIRE\Desktop\env\env03\Lib\site-packages\rest_framework\serializers.py", line 235, in is_valid
    raise ValidationError(self.errors)
rest_framework.exceptions.ValidationError: {'address': [ErrorDetail(string='This field is required.', code='required')], 'username': [ErrorDetail(string='This field is required.', code='required')], 'password': [ErrorDetail(string='This field is required.', code='required')]}
03/05/2023 10:56:31 AM : logging_confiq.logger : 
Traceback (most recent call last):
  File "C:\Users\RJ EMPIRE\Desktop\Django\FundooNotes\user_auth\views.py", line 28, in post
    serializer.is_valid(raise_exception=True)
  File "C:\Users\RJ EMPIRE\Desktop\env\env03\Lib\site-packages\rest_framework\serializers.py", line 235, in is_valid
    raise ValidationError(self.errors)
rest_framework.exceptions.ValidationError: {'username': [ErrorDetail(string='This field may not be blank.', code='blank')]}
03/05/2023 10:56:31 AM : logging_confiq.logger : 
Traceback (most recent call last):
  File "C:\Users\RJ EMPIRE\Desktop\Django\FundooNotes\user_auth\views.py", line 28, in post
    serializer.is_valid(raise_exception=True)
  File "C:\Users\RJ EMPIRE\Desktop\env\env03\Lib\site-packages\rest_framework\serializers.py", line 235, in is_valid
    raise ValidationError(self.errors)
rest_framework.exceptions.ValidationError: {'username': [ErrorDetail(string='This field may not be blank.', code='blank')]}
03/05/2023 11:29:31 AM : logging_confiq.logger : 
Traceback (most recent call last):
  File "C:\Users\RJ EMPIRE\Desktop\Django\FundooNotes\Notes\views.py", line 218, in post
    note.collaborators.add(user)
    ^^^^^^^^^^^^^^^^^^
AttributeError: 'Notes' object has no attribute 'collaborators'
03/05/2023 11:29:31 AM : logging_confiq.logger : 
Traceback (most recent call last):
  File "C:\Users\RJ EMPIRE\Desktop\Django\FundooNotes\Notes\views.py", line 218, in post
    note.collaborators.add(user)
    ^^^^^^^^^^^^^^^^^^
AttributeError: 'Notes' object has no attribute 'collaborators'
03/05/2023 11:30:11 AM : logging_confiq.logger : 
Traceback (most recent call last):
  File "C:\Users\RJ EMPIRE\Desktop\Django\FundooNotes\Notes\views.py", line 218, in post
    note.collaborators.add(user)
    ^^^^^^^^^^^^^^^^^^
AttributeError: 'Notes' object has no attribute 'collaborators'
03/05/2023 11:30:11 AM : logging_confiq.logger : 
Traceback (most recent call last):
  File "C:\Users\RJ EMPIRE\Desktop\Django\FundooNotes\Notes\views.py", line 218, in post
    note.collaborators.add(user)
    ^^^^^^^^^^^^^^^^^^
AttributeError: 'Notes' object has no attribute 'collaborators'
03/05/2023 11:30:17 AM : logging_confiq.logger : 
Traceback (most recent call last):
  File "C:\Users\RJ EMPIRE\Desktop\Django\FundooNotes\Notes\views.py", line 218, in post
    note.collaborators.add(user)
    ^^^^^^^^^^^^^^^^^^
AttributeError: 'Notes' object has no attribute 'collaborators'
03/05/2023 11:30:17 AM : logging_confiq.logger : 
Traceback (most recent call last):
  File "C:\Users\RJ EMPIRE\Desktop\Django\FundooNotes\Notes\views.py", line 218, in post
    note.collaborators.add(user)
    ^^^^^^^^^^^^^^^^^^
AttributeError: 'Notes' object has no attribute 'collaborators'
03/05/2023 11:30:34 AM : logging_confiq.logger : 
Traceback (most recent call last):
  File "C:\Users\RJ EMPIRE\Desktop\Django\FundooNotes\Notes\views.py", line 218, in post
    note.collaborators.add(user)
    ^^^^^^^^^^^^^^^^^^
AttributeError: 'Notes' object has no attribute 'collaborators'
03/05/2023 11:30:34 AM : logging_confiq.logger : 
Traceback (most recent call last):
  File "C:\Users\RJ EMPIRE\Desktop\Django\FundooNotes\Notes\views.py", line 218, in post
    note.collaborators.add(user)
    ^^^^^^^^^^^^^^^^^^
AttributeError: 'Notes' object has no attribute 'collaborators'
03/05/2023 11:31:13 AM : logging_confiq.logger : 
Traceback (most recent call last):
  File "C:\Users\RJ EMPIRE\Desktop\Django\FundooNotes\Notes\views.py", line 218, in post
    note.collaborators.add(user)
    ^^^^^^^^^^^^^^^^^^
AttributeError: 'Notes' object has no attribute 'collaborators'
03/05/2023 11:31:13 AM : logging_confiq.logger : 
Traceback (most recent call last):
  File "C:\Users\RJ EMPIRE\Desktop\Django\FundooNotes\Notes\views.py", line 218, in post
    note.collaborators.add(user)
    ^^^^^^^^^^^^^^^^^^
AttributeError: 'Notes' object has no attribute 'collaborators'
03/05/2023 12:49:14 PM : logging_confiq.logger : 
Traceback (most recent call last):
  File "C:\Users\RJ EMPIRE\Desktop\env\env03\Lib\site-packages\rest_framework\parsers.py", line 64, in parse
    return json.load(decoded_stream, parse_constant=parse_constant)
           ^^^^^^^^^^^^^^^^^^^^^^^^^^^^^^^^^^^^^^^^^^^^^^^^^^^^^^^^
  File "C:\Users\RJ EMPIRE\Desktop\env\env03\Lib\site-packages\rest_framework\utils\json.py", line 31, in load
    return json.load(*args, **kwargs)
           ^^^^^^^^^^^^^^^^^^^^^^^^^^
  File "C:\Python311\Lib\json\__init__.py", line 293, in load
    return loads(fp.read(),
           ^^^^^^^^^^^^^^^^
  File "C:\Python311\Lib\json\__init__.py", line 359, in loads
    return cls(**kw).decode(s)
           ^^^^^^^^^^^^^^^^^^^
  File "C:\Python311\Lib\json\decoder.py", line 340, in decode
    raise JSONDecodeError("Extra data", s, end)
json.decoder.JSONDecodeError: Extra data: line 1 column 12 (char 11)

During handling of the above exception, another exception occurred:

Traceback (most recent call last):
  File "C:\Users\RJ EMPIRE\Desktop\Django\FundooNotes\Notes\views.py", line 232, in post
    collaborator_data = request.data.get('collaborator')
                        ^^^^^^^^^^^^
  File "C:\Users\RJ EMPIRE\Desktop\env\env03\Lib\site-packages\rest_framework\request.py", line 216, in data
    self._load_data_and_files()
  File "C:\Users\RJ EMPIRE\Desktop\env\env03\Lib\site-packages\rest_framework\request.py", line 279, in _load_data_and_files
    self._data, self._files = self._parse()
                              ^^^^^^^^^^^^^
  File "C:\Users\RJ EMPIRE\Desktop\env\env03\Lib\site-packages\rest_framework\request.py", line 354, in _parse
    parsed = parser.parse(stream, media_type, self.parser_context)
             ^^^^^^^^^^^^^^^^^^^^^^^^^^^^^^^^^^^^^^^^^^^^^^^^^^^^^
  File "C:\Users\RJ EMPIRE\Desktop\env\env03\Lib\site-packages\rest_framework\parsers.py", line 66, in parse
    raise ParseError('JSON parse error - %s' % str(exc))
rest_framework.exceptions.ParseError: JSON parse error - Extra data: line 1 column 12 (char 11)
03/05/2023 12:49:14 PM : logging_confiq.logger : 
Traceback (most recent call last):
  File "C:\Users\RJ EMPIRE\Desktop\env\env03\Lib\site-packages\rest_framework\parsers.py", line 64, in parse
    return json.load(decoded_stream, parse_constant=parse_constant)
           ^^^^^^^^^^^^^^^^^^^^^^^^^^^^^^^^^^^^^^^^^^^^^^^^^^^^^^^^
  File "C:\Users\RJ EMPIRE\Desktop\env\env03\Lib\site-packages\rest_framework\utils\json.py", line 31, in load
    return json.load(*args, **kwargs)
           ^^^^^^^^^^^^^^^^^^^^^^^^^^
  File "C:\Python311\Lib\json\__init__.py", line 293, in load
    return loads(fp.read(),
           ^^^^^^^^^^^^^^^^
  File "C:\Python311\Lib\json\__init__.py", line 359, in loads
    return cls(**kw).decode(s)
           ^^^^^^^^^^^^^^^^^^^
  File "C:\Python311\Lib\json\decoder.py", line 340, in decode
    raise JSONDecodeError("Extra data", s, end)
json.decoder.JSONDecodeError: Extra data: line 1 column 12 (char 11)

During handling of the above exception, another exception occurred:

Traceback (most recent call last):
  File "C:\Users\RJ EMPIRE\Desktop\Django\FundooNotes\Notes\views.py", line 232, in post
    collaborator_data = request.data.get('collaborator')
                        ^^^^^^^^^^^^
  File "C:\Users\RJ EMPIRE\Desktop\env\env03\Lib\site-packages\rest_framework\request.py", line 216, in data
    self._load_data_and_files()
  File "C:\Users\RJ EMPIRE\Desktop\env\env03\Lib\site-packages\rest_framework\request.py", line 279, in _load_data_and_files
    self._data, self._files = self._parse()
                              ^^^^^^^^^^^^^
  File "C:\Users\RJ EMPIRE\Desktop\env\env03\Lib\site-packages\rest_framework\request.py", line 354, in _parse
    parsed = parser.parse(stream, media_type, self.parser_context)
             ^^^^^^^^^^^^^^^^^^^^^^^^^^^^^^^^^^^^^^^^^^^^^^^^^^^^^
  File "C:\Users\RJ EMPIRE\Desktop\env\env03\Lib\site-packages\rest_framework\parsers.py", line 66, in parse
    raise ParseError('JSON parse error - %s' % str(exc))
rest_framework.exceptions.ParseError: JSON parse error - Extra data: line 1 column 12 (char 11)
03/05/2023 12:50:53 PM : logging_confiq.logger : 
Traceback (most recent call last):
  File "C:\Users\RJ EMPIRE\Desktop\Django\FundooNotes\Notes\views.py", line 234, in post
    if collaborator_data.isdigit():  # If input is user_id
       ^^^^^^^^^^^^^^^^^^^^^^^^^
AttributeError: 'NoneType' object has no attribute 'isdigit'
03/05/2023 12:50:53 PM : logging_confiq.logger : 
Traceback (most recent call last):
  File "C:\Users\RJ EMPIRE\Desktop\Django\FundooNotes\Notes\views.py", line 234, in post
    if collaborator_data.isdigit():  # If input is user_id
       ^^^^^^^^^^^^^^^^^^^^^^^^^
AttributeError: 'NoneType' object has no attribute 'isdigit'
03/05/2023 12:52:47 PM : logging_confiq.logger : 
Traceback (most recent call last):
  File "C:\Users\RJ EMPIRE\Desktop\Django\FundooNotes\Notes\views.py", line 234, in post
    if collaborator_data.isdigit():  # If input is user_id
       ^^^^^^^^^^^^^^^^^^^^^^^^^
AttributeError: 'NoneType' object has no attribute 'isdigit'
03/05/2023 12:52:47 PM : logging_confiq.logger : 
Traceback (most recent call last):
  File "C:\Users\RJ EMPIRE\Desktop\Django\FundooNotes\Notes\views.py", line 234, in post
    if collaborator_data.isdigit():  # If input is user_id
       ^^^^^^^^^^^^^^^^^^^^^^^^^
AttributeError: 'NoneType' object has no attribute 'isdigit'
03/05/2023 12:53:33 PM : logging_confiq.logger : 
Traceback (most recent call last):
  File "C:\Users\RJ EMPIRE\Desktop\Django\FundooNotes\Notes\views.py", line 234, in post
    if collaborator_data.isdigit():  # If input is user_id
       ^^^^^^^^^^^^^^^^^^^^^^^^^
AttributeError: 'NoneType' object has no attribute 'isdigit'
03/05/2023 12:53:33 PM : logging_confiq.logger : 
Traceback (most recent call last):
  File "C:\Users\RJ EMPIRE\Desktop\Django\FundooNotes\Notes\views.py", line 234, in post
    if collaborator_data.isdigit():  # If input is user_id
       ^^^^^^^^^^^^^^^^^^^^^^^^^
AttributeError: 'NoneType' object has no attribute 'isdigit'
03/05/2023 12:55:44 PM : logging_confiq.logger : 
Traceback (most recent call last):
  File "C:\Users\RJ EMPIRE\Desktop\Django\FundooNotes\Notes\views.py", line 236, in post
    elif '@' in collaborator_data:  # If input is email
         ^^^^^^^^^^^^^^^^^^^^^^^^
TypeError: argument of type 'NoneType' is not iterable
03/05/2023 12:55:44 PM : logging_confiq.logger : 
Traceback (most recent call last):
  File "C:\Users\RJ EMPIRE\Desktop\Django\FundooNotes\Notes\views.py", line 236, in post
    elif '@' in collaborator_data:  # If input is email
         ^^^^^^^^^^^^^^^^^^^^^^^^
TypeError: argument of type 'NoneType' is not iterable
03/05/2023 01:11:30 PM : logging_confiq.logger : 
Traceback (most recent call last):
  File "C:\Users\RJ EMPIRE\Desktop\Django\FundooNotes\Notes\views.py", line 238, in post
    collaborator = CustomUser.objects.get(email=collaborator_data)
                   ^^^^^^^^^^^^^^^^^^^^^^^^^^^^^^^^^^^^^^^^^^^^^^^
  File "C:\Users\RJ EMPIRE\Desktop\env\env03\Lib\site-packages\django\db\models\manager.py", line 85, in manager_method
    return getattr(self.get_queryset(), name)(*args, **kwargs)
           ^^^^^^^^^^^^^^^^^^^^^^^^^^^^^^^^^^^^^^^^^^^^^^^^^^^
  File "C:\Users\RJ EMPIRE\Desktop\env\env03\Lib\site-packages\django\db\models\query.py", line 653, in get
    raise self.model.MultipleObjectsReturned(
user_auth.models.CustomUser.MultipleObjectsReturned: get() returned more than one CustomUser -- it returned 2!
03/05/2023 01:11:30 PM : logging_confiq.logger : 
Traceback (most recent call last):
  File "C:\Users\RJ EMPIRE\Desktop\Django\FundooNotes\Notes\views.py", line 238, in post
    collaborator = CustomUser.objects.get(email=collaborator_data)
                   ^^^^^^^^^^^^^^^^^^^^^^^^^^^^^^^^^^^^^^^^^^^^^^^
  File "C:\Users\RJ EMPIRE\Desktop\env\env03\Lib\site-packages\django\db\models\manager.py", line 85, in manager_method
    return getattr(self.get_queryset(), name)(*args, **kwargs)
           ^^^^^^^^^^^^^^^^^^^^^^^^^^^^^^^^^^^^^^^^^^^^^^^^^^^
  File "C:\Users\RJ EMPIRE\Desktop\env\env03\Lib\site-packages\django\db\models\query.py", line 653, in get
    raise self.model.MultipleObjectsReturned(
user_auth.models.CustomUser.MultipleObjectsReturned: get() returned more than one CustomUser -- it returned 2!
03/05/2023 09:00:35 PM : logging_confiq.logger : 
Traceback (most recent call last):
  File "C:\Users\RJ EMPIRE\Desktop\Django\FundooNotes\Notes\views.py", line 28, in post
    serializer.is_valid(raise_exception=True)
  File "C:\Users\RJ EMPIRE\Desktop\env\env03\Lib\site-packages\rest_framework\serializers.py", line 227, in is_valid
    self._validated_data = self.run_validation(self.initial_data)
                           ^^^^^^^^^^^^^^^^^^^^^^^^^^^^^^^^^^^^^^
  File "C:\Users\RJ EMPIRE\Desktop\env\env03\Lib\site-packages\rest_framework\serializers.py", line 426, in run_validation
    value = self.to_internal_value(data)
            ^^^^^^^^^^^^^^^^^^^^^^^^^^^^
  File "C:\Users\RJ EMPIRE\Desktop\env\env03\Lib\site-packages\rest_framework\serializers.py", line 479, in to_internal_value
    for field in fields:
  File "C:\Users\RJ EMPIRE\Desktop\env\env03\Lib\site-packages\rest_framework\serializers.py", line 362, in _writable_fields
    for field in self.fields.values():
                 ^^^^^^^^^^^
  File "C:\Users\RJ EMPIRE\Desktop\env\env03\Lib\site-packages\django\utils\functional.py", line 57, in __get__
    res = instance.__dict__[self.name] = self.func(instance)
                                         ^^^^^^^^^^^^^^^^^^^
  File "C:\Users\RJ EMPIRE\Desktop\env\env03\Lib\site-packages\rest_framework\serializers.py", line 356, in fields
    for key, value in self.get_fields().items():
                      ^^^^^^^^^^^^^^^^^
  File "C:\Users\RJ EMPIRE\Desktop\env\env03\Lib\site-packages\rest_framework\serializers.py", line 1076, in get_fields
    field_class, field_kwargs = self.build_field(
                                ^^^^^^^^^^^^^^^^^
  File "C:\Users\RJ EMPIRE\Desktop\env\env03\Lib\site-packages\rest_framework\serializers.py", line 1222, in build_field
    return self.build_unknown_field(field_name, model_class)
           ^^^^^^^^^^^^^^^^^^^^^^^^^^^^^^^^^^^^^^^^^^^^^^^^^
  File "C:\Users\RJ EMPIRE\Desktop\env\env03\Lib\site-packages\rest_framework\serializers.py", line 1340, in build_unknown_field
    raise ImproperlyConfigured(
django.core.exceptions.ImproperlyConfigured: Field name `collaborators` is not valid for model `Notes`.
03/05/2023 09:00:35 PM : logging_confiq.logger : 
Traceback (most recent call last):
  File "C:\Users\RJ EMPIRE\Desktop\Django\FundooNotes\Notes\views.py", line 28, in post
    serializer.is_valid(raise_exception=True)
  File "C:\Users\RJ EMPIRE\Desktop\env\env03\Lib\site-packages\rest_framework\serializers.py", line 227, in is_valid
    self._validated_data = self.run_validation(self.initial_data)
                           ^^^^^^^^^^^^^^^^^^^^^^^^^^^^^^^^^^^^^^
  File "C:\Users\RJ EMPIRE\Desktop\env\env03\Lib\site-packages\rest_framework\serializers.py", line 426, in run_validation
    value = self.to_internal_value(data)
            ^^^^^^^^^^^^^^^^^^^^^^^^^^^^
  File "C:\Users\RJ EMPIRE\Desktop\env\env03\Lib\site-packages\rest_framework\serializers.py", line 479, in to_internal_value
    for field in fields:
  File "C:\Users\RJ EMPIRE\Desktop\env\env03\Lib\site-packages\rest_framework\serializers.py", line 362, in _writable_fields
    for field in self.fields.values():
                 ^^^^^^^^^^^
  File "C:\Users\RJ EMPIRE\Desktop\env\env03\Lib\site-packages\django\utils\functional.py", line 57, in __get__
    res = instance.__dict__[self.name] = self.func(instance)
                                         ^^^^^^^^^^^^^^^^^^^
  File "C:\Users\RJ EMPIRE\Desktop\env\env03\Lib\site-packages\rest_framework\serializers.py", line 356, in fields
    for key, value in self.get_fields().items():
                      ^^^^^^^^^^^^^^^^^
  File "C:\Users\RJ EMPIRE\Desktop\env\env03\Lib\site-packages\rest_framework\serializers.py", line 1076, in get_fields
    field_class, field_kwargs = self.build_field(
                                ^^^^^^^^^^^^^^^^^
  File "C:\Users\RJ EMPIRE\Desktop\env\env03\Lib\site-packages\rest_framework\serializers.py", line 1222, in build_field
    return self.build_unknown_field(field_name, model_class)
           ^^^^^^^^^^^^^^^^^^^^^^^^^^^^^^^^^^^^^^^^^^^^^^^^^
  File "C:\Users\RJ EMPIRE\Desktop\env\env03\Lib\site-packages\rest_framework\serializers.py", line 1340, in build_unknown_field
    raise ImproperlyConfigured(
django.core.exceptions.ImproperlyConfigured: Field name `collaborators` is not valid for model `Notes`.
03/05/2023 09:02:05 PM : logging_confiq.logger : 
Traceback (most recent call last):
  File "C:\Users\RJ EMPIRE\Desktop\Django\FundooNotes\Notes\views.py", line 28, in post
    serializer.is_valid(raise_exception=True)
  File "C:\Users\RJ EMPIRE\Desktop\env\env03\Lib\site-packages\rest_framework\serializers.py", line 227, in is_valid
    self._validated_data = self.run_validation(self.initial_data)
                           ^^^^^^^^^^^^^^^^^^^^^^^^^^^^^^^^^^^^^^
  File "C:\Users\RJ EMPIRE\Desktop\env\env03\Lib\site-packages\rest_framework\serializers.py", line 426, in run_validation
    value = self.to_internal_value(data)
            ^^^^^^^^^^^^^^^^^^^^^^^^^^^^
  File "C:\Users\RJ EMPIRE\Desktop\env\env03\Lib\site-packages\rest_framework\serializers.py", line 479, in to_internal_value
    for field in fields:
  File "C:\Users\RJ EMPIRE\Desktop\env\env03\Lib\site-packages\rest_framework\serializers.py", line 362, in _writable_fields
    for field in self.fields.values():
                 ^^^^^^^^^^^
  File "C:\Users\RJ EMPIRE\Desktop\env\env03\Lib\site-packages\django\utils\functional.py", line 57, in __get__
    res = instance.__dict__[self.name] = self.func(instance)
                                         ^^^^^^^^^^^^^^^^^^^
  File "C:\Users\RJ EMPIRE\Desktop\env\env03\Lib\site-packages\rest_framework\serializers.py", line 356, in fields
    for key, value in self.get_fields().items():
                      ^^^^^^^^^^^^^^^^^
  File "C:\Users\RJ EMPIRE\Desktop\env\env03\Lib\site-packages\rest_framework\serializers.py", line 1076, in get_fields
    field_class, field_kwargs = self.build_field(
                                ^^^^^^^^^^^^^^^^^
  File "C:\Users\RJ EMPIRE\Desktop\env\env03\Lib\site-packages\rest_framework\serializers.py", line 1222, in build_field
    return self.build_unknown_field(field_name, model_class)
           ^^^^^^^^^^^^^^^^^^^^^^^^^^^^^^^^^^^^^^^^^^^^^^^^^
  File "C:\Users\RJ EMPIRE\Desktop\env\env03\Lib\site-packages\rest_framework\serializers.py", line 1340, in build_unknown_field
    raise ImproperlyConfigured(
django.core.exceptions.ImproperlyConfigured: Field name `collaborators` is not valid for model `Notes`.
03/05/2023 09:02:05 PM : logging_confiq.logger : 
Traceback (most recent call last):
  File "C:\Users\RJ EMPIRE\Desktop\Django\FundooNotes\Notes\views.py", line 28, in post
    serializer.is_valid(raise_exception=True)
  File "C:\Users\RJ EMPIRE\Desktop\env\env03\Lib\site-packages\rest_framework\serializers.py", line 227, in is_valid
    self._validated_data = self.run_validation(self.initial_data)
                           ^^^^^^^^^^^^^^^^^^^^^^^^^^^^^^^^^^^^^^
  File "C:\Users\RJ EMPIRE\Desktop\env\env03\Lib\site-packages\rest_framework\serializers.py", line 426, in run_validation
    value = self.to_internal_value(data)
            ^^^^^^^^^^^^^^^^^^^^^^^^^^^^
  File "C:\Users\RJ EMPIRE\Desktop\env\env03\Lib\site-packages\rest_framework\serializers.py", line 479, in to_internal_value
    for field in fields:
  File "C:\Users\RJ EMPIRE\Desktop\env\env03\Lib\site-packages\rest_framework\serializers.py", line 362, in _writable_fields
    for field in self.fields.values():
                 ^^^^^^^^^^^
  File "C:\Users\RJ EMPIRE\Desktop\env\env03\Lib\site-packages\django\utils\functional.py", line 57, in __get__
    res = instance.__dict__[self.name] = self.func(instance)
                                         ^^^^^^^^^^^^^^^^^^^
  File "C:\Users\RJ EMPIRE\Desktop\env\env03\Lib\site-packages\rest_framework\serializers.py", line 356, in fields
    for key, value in self.get_fields().items():
                      ^^^^^^^^^^^^^^^^^
  File "C:\Users\RJ EMPIRE\Desktop\env\env03\Lib\site-packages\rest_framework\serializers.py", line 1076, in get_fields
    field_class, field_kwargs = self.build_field(
                                ^^^^^^^^^^^^^^^^^
  File "C:\Users\RJ EMPIRE\Desktop\env\env03\Lib\site-packages\rest_framework\serializers.py", line 1222, in build_field
    return self.build_unknown_field(field_name, model_class)
           ^^^^^^^^^^^^^^^^^^^^^^^^^^^^^^^^^^^^^^^^^^^^^^^^^
  File "C:\Users\RJ EMPIRE\Desktop\env\env03\Lib\site-packages\rest_framework\serializers.py", line 1340, in build_unknown_field
    raise ImproperlyConfigured(
django.core.exceptions.ImproperlyConfigured: Field name `collaborators` is not valid for model `Notes`.
03/05/2023 09:10:51 PM : logging_confiq.logger : 
Traceback (most recent call last):
  File "C:\Users\RJ EMPIRE\Desktop\env\env03\Lib\site-packages\django\db\models\fields\__init__.py", line 2018, in get_prep_value
    return int(value)
           ^^^^^^^^^^
TypeError: int() argument must be a string, a bytes-like object or a real number, not 'list'

The above exception was the direct cause of the following exception:

Traceback (most recent call last):
  File "C:\Users\RJ EMPIRE\Desktop\Django\FundooNotes\Notes\views.py", line 29, in post
    serializer.save()
  File "C:\Users\RJ EMPIRE\Desktop\env\env03\Lib\site-packages\rest_framework\serializers.py", line 212, in save
    self.instance = self.create(validated_data)
                    ^^^^^^^^^^^^^^^^^^^^^^^^^^^
  File "C:\Users\RJ EMPIRE\Desktop\Django\FundooNotes\Notes\serializers.py", line 30, in create
    notes.collaborator.add(collab)
  File "C:\Users\RJ EMPIRE\Desktop\env\env03\Lib\site-packages\django\db\models\fields\related_descriptors.py", line 1087, in add
    self._add_items(
  File "C:\Users\RJ EMPIRE\Desktop\env\env03\Lib\site-packages\django\db\models\fields\related_descriptors.py", line 1323, in _add_items
    target_ids = self._get_target_ids(target_field_name, objs)
                 ^^^^^^^^^^^^^^^^^^^^^^^^^^^^^^^^^^^^^^^^^^^^^
  File "C:\Users\RJ EMPIRE\Desktop\env\env03\Lib\site-packages\django\db\models\fields\related_descriptors.py", line 1257, in _get_target_ids
    target_ids.add(target_field.get_prep_value(obj))
                   ^^^^^^^^^^^^^^^^^^^^^^^^^^^^^^^^
  File "C:\Users\RJ EMPIRE\Desktop\env\env03\Lib\site-packages\django\db\models\fields\related.py", line 1152, in get_prep_value
    return self.target_field.get_prep_value(value)
           ^^^^^^^^^^^^^^^^^^^^^^^^^^^^^^^^^^^^^^^
  File "C:\Users\RJ EMPIRE\Desktop\env\env03\Lib\site-packages\django\db\models\fields\__init__.py", line 2020, in get_prep_value
    raise e.__class__(
TypeError: Field 'id' expected a number but got [3, 7].
03/05/2023 09:10:51 PM : logging_confiq.logger : 
Traceback (most recent call last):
  File "C:\Users\RJ EMPIRE\Desktop\env\env03\Lib\site-packages\django\db\models\fields\__init__.py", line 2018, in get_prep_value
    return int(value)
           ^^^^^^^^^^
TypeError: int() argument must be a string, a bytes-like object or a real number, not 'list'

The above exception was the direct cause of the following exception:

Traceback (most recent call last):
  File "C:\Users\RJ EMPIRE\Desktop\Django\FundooNotes\Notes\views.py", line 29, in post
    serializer.save()
  File "C:\Users\RJ EMPIRE\Desktop\env\env03\Lib\site-packages\rest_framework\serializers.py", line 212, in save
    self.instance = self.create(validated_data)
                    ^^^^^^^^^^^^^^^^^^^^^^^^^^^
  File "C:\Users\RJ EMPIRE\Desktop\Django\FundooNotes\Notes\serializers.py", line 30, in create
    notes.collaborator.add(collab)
  File "C:\Users\RJ EMPIRE\Desktop\env\env03\Lib\site-packages\django\db\models\fields\related_descriptors.py", line 1087, in add
    self._add_items(
  File "C:\Users\RJ EMPIRE\Desktop\env\env03\Lib\site-packages\django\db\models\fields\related_descriptors.py", line 1323, in _add_items
    target_ids = self._get_target_ids(target_field_name, objs)
                 ^^^^^^^^^^^^^^^^^^^^^^^^^^^^^^^^^^^^^^^^^^^^^
  File "C:\Users\RJ EMPIRE\Desktop\env\env03\Lib\site-packages\django\db\models\fields\related_descriptors.py", line 1257, in _get_target_ids
    target_ids.add(target_field.get_prep_value(obj))
                   ^^^^^^^^^^^^^^^^^^^^^^^^^^^^^^^^
  File "C:\Users\RJ EMPIRE\Desktop\env\env03\Lib\site-packages\django\db\models\fields\related.py", line 1152, in get_prep_value
    return self.target_field.get_prep_value(value)
           ^^^^^^^^^^^^^^^^^^^^^^^^^^^^^^^^^^^^^^^
  File "C:\Users\RJ EMPIRE\Desktop\env\env03\Lib\site-packages\django\db\models\fields\__init__.py", line 2020, in get_prep_value
    raise e.__class__(
TypeError: Field 'id' expected a number but got [3, 7].
03/06/2023 09:34:33 AM : logging_confiq.logger : 
Traceback (most recent call last):
  File "C:\Users\RJ EMPIRE\Desktop\Django\FundooNotes\Notes\views.py", line 218, in post
    CustomUser.objects.get(pk=user_id)
  File "C:\Users\RJ EMPIRE\Desktop\env\env03\Lib\site-packages\django\db\models\manager.py", line 85, in manager_method
    return getattr(self.get_queryset(), name)(*args, **kwargs)
           ^^^^^^^^^^^^^^^^^^^^^^^^^^^^^^^^^^^^^^^^^^^^^^^^^^^
  File "C:\Users\RJ EMPIRE\Desktop\env\env03\Lib\site-packages\django\db\models\query.py", line 650, in get
    raise self.model.DoesNotExist(
user_auth.models.CustomUser.DoesNotExist: CustomUser matching query does not exist.
03/06/2023 09:34:33 AM : logging_confiq.logger : 
Traceback (most recent call last):
  File "C:\Users\RJ EMPIRE\Desktop\Django\FundooNotes\Notes\views.py", line 218, in post
    CustomUser.objects.get(pk=user_id)
  File "C:\Users\RJ EMPIRE\Desktop\env\env03\Lib\site-packages\django\db\models\manager.py", line 85, in manager_method
    return getattr(self.get_queryset(), name)(*args, **kwargs)
           ^^^^^^^^^^^^^^^^^^^^^^^^^^^^^^^^^^^^^^^^^^^^^^^^^^^
  File "C:\Users\RJ EMPIRE\Desktop\env\env03\Lib\site-packages\django\db\models\query.py", line 650, in get
    raise self.model.DoesNotExist(
user_auth.models.CustomUser.DoesNotExist: CustomUser matching query does not exist.
03/06/2023 11:11:46 AM : logging_confiq.logger : 
Traceback (most recent call last):
  File "C:\Users\RJ EMPIRE\Desktop\env\env03\Lib\site-packages\django\db\models\fields\__init__.py", line 2018, in get_prep_value
    return int(value)
           ^^^^^^^^^^
TypeError: int() argument must be a string, a bytes-like object or a real number, not 'CustomUser'

The above exception was the direct cause of the following exception:

Traceback (most recent call last):
  File "C:\Users\RJ EMPIRE\Desktop\Django\FundooNotes\Notes\views.py", line 52, in get
    notes = Notes.objects.filter(Q(user__id=request.user) | Q(collaborator__id=request.user)).distinct()
            ^^^^^^^^^^^^^^^^^^^^^^^^^^^^^^^^^^^^^^^^^^^^^^^^^^^^^^^^^^^^^^^^^^^^^^^^^^^^^^^^^
  File "C:\Users\RJ EMPIRE\Desktop\env\env03\Lib\site-packages\django\db\models\manager.py", line 85, in manager_method
    return getattr(self.get_queryset(), name)(*args, **kwargs)
           ^^^^^^^^^^^^^^^^^^^^^^^^^^^^^^^^^^^^^^^^^^^^^^^^^^^
  File "C:\Users\RJ EMPIRE\Desktop\env\env03\Lib\site-packages\django\db\models\query.py", line 1421, in filter
    return self._filter_or_exclude(False, args, kwargs)
           ^^^^^^^^^^^^^^^^^^^^^^^^^^^^^^^^^^^^^^^^^^^^
  File "C:\Users\RJ EMPIRE\Desktop\env\env03\Lib\site-packages\django\db\models\query.py", line 1439, in _filter_or_exclude
    clone._filter_or_exclude_inplace(negate, args, kwargs)
  File "C:\Users\RJ EMPIRE\Desktop\env\env03\Lib\site-packages\django\db\models\query.py", line 1446, in _filter_or_exclude_inplace
    self._query.add_q(Q(*args, **kwargs))
  File "C:\Users\RJ EMPIRE\Desktop\env\env03\Lib\site-packages\django\db\models\sql\query.py", line 1532, in add_q
    clause, _ = self._add_q(q_object, self.used_aliases)
                ^^^^^^^^^^^^^^^^^^^^^^^^^^^^^^^^^^^^^^^^
  File "C:\Users\RJ EMPIRE\Desktop\env\env03\Lib\site-packages\django\db\models\sql\query.py", line 1562, in _add_q
    child_clause, needed_inner = self.build_filter(
                                 ^^^^^^^^^^^^^^^^^^
  File "C:\Users\RJ EMPIRE\Desktop\env\env03\Lib\site-packages\django\db\models\sql\query.py", line 1388, in build_filter
    return self._add_q(
           ^^^^^^^^^^^^
  File "C:\Users\RJ EMPIRE\Desktop\env\env03\Lib\site-packages\django\db\models\sql\query.py", line 1562, in _add_q
    child_clause, needed_inner = self.build_filter(
                                 ^^^^^^^^^^^^^^^^^^
  File "C:\Users\RJ EMPIRE\Desktop\env\env03\Lib\site-packages\django\db\models\sql\query.py", line 1478, in build_filter
    condition = self.build_lookup(lookups, col, value)
                ^^^^^^^^^^^^^^^^^^^^^^^^^^^^^^^^^^^^^^
  File "C:\Users\RJ EMPIRE\Desktop\env\env03\Lib\site-packages\django\db\models\sql\query.py", line 1303, in build_lookup
    lookup = lookup_class(lhs, rhs)
             ^^^^^^^^^^^^^^^^^^^^^^
  File "C:\Users\RJ EMPIRE\Desktop\env\env03\Lib\site-packages\django\db\models\lookups.py", line 27, in __init__
    self.rhs = self.get_prep_lookup()
               ^^^^^^^^^^^^^^^^^^^^^^
  File "C:\Users\RJ EMPIRE\Desktop\env\env03\Lib\site-packages\django\db\models\lookups.py", line 341, in get_prep_lookup
    return super().get_prep_lookup()
           ^^^^^^^^^^^^^^^^^^^^^^^^^
  File "C:\Users\RJ EMPIRE\Desktop\env\env03\Lib\site-packages\django\db\models\lookups.py", line 85, in get_prep_lookup
    return self.lhs.output_field.get_prep_value(self.rhs)
           ^^^^^^^^^^^^^^^^^^^^^^^^^^^^^^^^^^^^^^^^^^^^^^
  File "C:\Users\RJ EMPIRE\Desktop\env\env03\Lib\site-packages\django\db\models\fields\__init__.py", line 2020, in get_prep_value
    raise e.__class__(
TypeError: Field 'id' expected a number but got <CustomUser: suraj>.
03/06/2023 11:11:46 AM : logging_confiq.logger : 
Traceback (most recent call last):
  File "C:\Users\RJ EMPIRE\Desktop\env\env03\Lib\site-packages\django\db\models\fields\__init__.py", line 2018, in get_prep_value
    return int(value)
           ^^^^^^^^^^
TypeError: int() argument must be a string, a bytes-like object or a real number, not 'CustomUser'

The above exception was the direct cause of the following exception:

Traceback (most recent call last):
  File "C:\Users\RJ EMPIRE\Desktop\Django\FundooNotes\Notes\views.py", line 52, in get
    notes = Notes.objects.filter(Q(user__id=request.user) | Q(collaborator__id=request.user)).distinct()
            ^^^^^^^^^^^^^^^^^^^^^^^^^^^^^^^^^^^^^^^^^^^^^^^^^^^^^^^^^^^^^^^^^^^^^^^^^^^^^^^^^
  File "C:\Users\RJ EMPIRE\Desktop\env\env03\Lib\site-packages\django\db\models\manager.py", line 85, in manager_method
    return getattr(self.get_queryset(), name)(*args, **kwargs)
           ^^^^^^^^^^^^^^^^^^^^^^^^^^^^^^^^^^^^^^^^^^^^^^^^^^^
  File "C:\Users\RJ EMPIRE\Desktop\env\env03\Lib\site-packages\django\db\models\query.py", line 1421, in filter
    return self._filter_or_exclude(False, args, kwargs)
           ^^^^^^^^^^^^^^^^^^^^^^^^^^^^^^^^^^^^^^^^^^^^
  File "C:\Users\RJ EMPIRE\Desktop\env\env03\Lib\site-packages\django\db\models\query.py", line 1439, in _filter_or_exclude
    clone._filter_or_exclude_inplace(negate, args, kwargs)
  File "C:\Users\RJ EMPIRE\Desktop\env\env03\Lib\site-packages\django\db\models\query.py", line 1446, in _filter_or_exclude_inplace
    self._query.add_q(Q(*args, **kwargs))
  File "C:\Users\RJ EMPIRE\Desktop\env\env03\Lib\site-packages\django\db\models\sql\query.py", line 1532, in add_q
    clause, _ = self._add_q(q_object, self.used_aliases)
                ^^^^^^^^^^^^^^^^^^^^^^^^^^^^^^^^^^^^^^^^
  File "C:\Users\RJ EMPIRE\Desktop\env\env03\Lib\site-packages\django\db\models\sql\query.py", line 1562, in _add_q
    child_clause, needed_inner = self.build_filter(
                                 ^^^^^^^^^^^^^^^^^^
  File "C:\Users\RJ EMPIRE\Desktop\env\env03\Lib\site-packages\django\db\models\sql\query.py", line 1388, in build_filter
    return self._add_q(
           ^^^^^^^^^^^^
  File "C:\Users\RJ EMPIRE\Desktop\env\env03\Lib\site-packages\django\db\models\sql\query.py", line 1562, in _add_q
    child_clause, needed_inner = self.build_filter(
                                 ^^^^^^^^^^^^^^^^^^
  File "C:\Users\RJ EMPIRE\Desktop\env\env03\Lib\site-packages\django\db\models\sql\query.py", line 1478, in build_filter
    condition = self.build_lookup(lookups, col, value)
                ^^^^^^^^^^^^^^^^^^^^^^^^^^^^^^^^^^^^^^
  File "C:\Users\RJ EMPIRE\Desktop\env\env03\Lib\site-packages\django\db\models\sql\query.py", line 1303, in build_lookup
    lookup = lookup_class(lhs, rhs)
             ^^^^^^^^^^^^^^^^^^^^^^
  File "C:\Users\RJ EMPIRE\Desktop\env\env03\Lib\site-packages\django\db\models\lookups.py", line 27, in __init__
    self.rhs = self.get_prep_lookup()
               ^^^^^^^^^^^^^^^^^^^^^^
  File "C:\Users\RJ EMPIRE\Desktop\env\env03\Lib\site-packages\django\db\models\lookups.py", line 341, in get_prep_lookup
    return super().get_prep_lookup()
           ^^^^^^^^^^^^^^^^^^^^^^^^^
  File "C:\Users\RJ EMPIRE\Desktop\env\env03\Lib\site-packages\django\db\models\lookups.py", line 85, in get_prep_lookup
    return self.lhs.output_field.get_prep_value(self.rhs)
           ^^^^^^^^^^^^^^^^^^^^^^^^^^^^^^^^^^^^^^^^^^^^^^
  File "C:\Users\RJ EMPIRE\Desktop\env\env03\Lib\site-packages\django\db\models\fields\__init__.py", line 2020, in get_prep_value
    raise e.__class__(
TypeError: Field 'id' expected a number but got <CustomUser: suraj>.
03/06/2023 12:11:08 PM : logging_confiq.logger : 
Traceback (most recent call last):
  File "C:\Users\RJ EMPIRE\Desktop\Django\FundooNotes\Notes\views.py", line 30, in post
    serializer.save()
  File "C:\Users\RJ EMPIRE\Desktop\env\env03\Lib\site-packages\rest_framework\serializers.py", line 212, in save
    self.instance = self.create(validated_data)
                    ^^^^^^^^^^^^^^^^^^^^^^^^^^^
  File "C:\Users\RJ EMPIRE\Desktop\Django\FundooNotes\Notes\serializers.py", line 29, in create
    collaborators = self.get_collaborator(collaborator_data)
                    ^^^^^^^^^^^^^^^^^^^^^^^^^^^^^^^^^^^^^^^^
  File "C:\Users\RJ EMPIRE\Desktop\Django\FundooNotes\Notes\serializers.py", line 53, in get_collaborator
    if data.isdigit():  # If input is user_id
       ^^^^^^^^^^^^
AttributeError: 'int' object has no attribute 'isdigit'
03/06/2023 12:11:08 PM : logging_confiq.logger : 
Traceback (most recent call last):
  File "C:\Users\RJ EMPIRE\Desktop\Django\FundooNotes\Notes\views.py", line 30, in post
    serializer.save()
  File "C:\Users\RJ EMPIRE\Desktop\env\env03\Lib\site-packages\rest_framework\serializers.py", line 212, in save
    self.instance = self.create(validated_data)
                    ^^^^^^^^^^^^^^^^^^^^^^^^^^^
  File "C:\Users\RJ EMPIRE\Desktop\Django\FundooNotes\Notes\serializers.py", line 29, in create
    collaborators = self.get_collaborator(collaborator_data)
                    ^^^^^^^^^^^^^^^^^^^^^^^^^^^^^^^^^^^^^^^^
  File "C:\Users\RJ EMPIRE\Desktop\Django\FundooNotes\Notes\serializers.py", line 53, in get_collaborator
    if data.isdigit():  # If input is user_id
       ^^^^^^^^^^^^
AttributeError: 'int' object has no attribute 'isdigit'
03/06/2023 12:18:33 PM : logging_confiq.logger : 
Traceback (most recent call last):
  File "C:\Users\RJ EMPIRE\Desktop\env\env03\Lib\site-packages\django\db\models\fields\__init__.py", line 2018, in get_prep_value
    return int(value)
           ^^^^^^^^^^
ValueError: invalid literal for int() with base 10: '['

The above exception was the direct cause of the following exception:

Traceback (most recent call last):
  File "C:\Users\RJ EMPIRE\Desktop\Django\FundooNotes\Notes\views.py", line 30, in post
    serializer.save()
  File "C:\Users\RJ EMPIRE\Desktop\env\env03\Lib\site-packages\rest_framework\serializers.py", line 212, in save
    self.instance = self.create(validated_data)
                    ^^^^^^^^^^^^^^^^^^^^^^^^^^^
  File "C:\Users\RJ EMPIRE\Desktop\Django\FundooNotes\Notes\serializers.py", line 29, in create
    collaborators = self.get_collaborator(collaborator_data)
                    ^^^^^^^^^^^^^^^^^^^^^^^^^^^^^^^^^^^^^^^^
  File "C:\Users\RJ EMPIRE\Desktop\Django\FundooNotes\Notes\serializers.py", line 64, in get_collaborator
    collaborator = CustomUser.objects.filter(id=data).first()
                   ^^^^^^^^^^^^^^^^^^^^^^^^^^^^^^^^^^
  File "C:\Users\RJ EMPIRE\Desktop\env\env03\Lib\site-packages\django\db\models\manager.py", line 85, in manager_method
    return getattr(self.get_queryset(), name)(*args, **kwargs)
           ^^^^^^^^^^^^^^^^^^^^^^^^^^^^^^^^^^^^^^^^^^^^^^^^^^^
  File "C:\Users\RJ EMPIRE\Desktop\env\env03\Lib\site-packages\django\db\models\query.py", line 1421, in filter
    return self._filter_or_exclude(False, args, kwargs)
           ^^^^^^^^^^^^^^^^^^^^^^^^^^^^^^^^^^^^^^^^^^^^
  File "C:\Users\RJ EMPIRE\Desktop\env\env03\Lib\site-packages\django\db\models\query.py", line 1439, in _filter_or_exclude
    clone._filter_or_exclude_inplace(negate, args, kwargs)
  File "C:\Users\RJ EMPIRE\Desktop\env\env03\Lib\site-packages\django\db\models\query.py", line 1446, in _filter_or_exclude_inplace
    self._query.add_q(Q(*args, **kwargs))
  File "C:\Users\RJ EMPIRE\Desktop\env\env03\Lib\site-packages\django\db\models\sql\query.py", line 1532, in add_q
    clause, _ = self._add_q(q_object, self.used_aliases)
                ^^^^^^^^^^^^^^^^^^^^^^^^^^^^^^^^^^^^^^^^
  File "C:\Users\RJ EMPIRE\Desktop\env\env03\Lib\site-packages\django\db\models\sql\query.py", line 1562, in _add_q
    child_clause, needed_inner = self.build_filter(
                                 ^^^^^^^^^^^^^^^^^^
  File "C:\Users\RJ EMPIRE\Desktop\env\env03\Lib\site-packages\django\db\models\sql\query.py", line 1478, in build_filter
    condition = self.build_lookup(lookups, col, value)
                ^^^^^^^^^^^^^^^^^^^^^^^^^^^^^^^^^^^^^^
  File "C:\Users\RJ EMPIRE\Desktop\env\env03\Lib\site-packages\django\db\models\sql\query.py", line 1303, in build_lookup
    lookup = lookup_class(lhs, rhs)
             ^^^^^^^^^^^^^^^^^^^^^^
  File "C:\Users\RJ EMPIRE\Desktop\env\env03\Lib\site-packages\django\db\models\lookups.py", line 27, in __init__
    self.rhs = self.get_prep_lookup()
               ^^^^^^^^^^^^^^^^^^^^^^
  File "C:\Users\RJ EMPIRE\Desktop\env\env03\Lib\site-packages\django\db\models\lookups.py", line 341, in get_prep_lookup
    return super().get_prep_lookup()
           ^^^^^^^^^^^^^^^^^^^^^^^^^
  File "C:\Users\RJ EMPIRE\Desktop\env\env03\Lib\site-packages\django\db\models\lookups.py", line 85, in get_prep_lookup
    return self.lhs.output_field.get_prep_value(self.rhs)
           ^^^^^^^^^^^^^^^^^^^^^^^^^^^^^^^^^^^^^^^^^^^^^^
  File "C:\Users\RJ EMPIRE\Desktop\env\env03\Lib\site-packages\django\db\models\fields\__init__.py", line 2020, in get_prep_value
    raise e.__class__(
ValueError: Field 'id' expected a number but got '['.
03/06/2023 12:18:33 PM : logging_confiq.logger : 
Traceback (most recent call last):
  File "C:\Users\RJ EMPIRE\Desktop\env\env03\Lib\site-packages\django\db\models\fields\__init__.py", line 2018, in get_prep_value
    return int(value)
           ^^^^^^^^^^
ValueError: invalid literal for int() with base 10: '['

The above exception was the direct cause of the following exception:

Traceback (most recent call last):
  File "C:\Users\RJ EMPIRE\Desktop\Django\FundooNotes\Notes\views.py", line 30, in post
    serializer.save()
  File "C:\Users\RJ EMPIRE\Desktop\env\env03\Lib\site-packages\rest_framework\serializers.py", line 212, in save
    self.instance = self.create(validated_data)
                    ^^^^^^^^^^^^^^^^^^^^^^^^^^^
  File "C:\Users\RJ EMPIRE\Desktop\Django\FundooNotes\Notes\serializers.py", line 29, in create
    collaborators = self.get_collaborator(collaborator_data)
                    ^^^^^^^^^^^^^^^^^^^^^^^^^^^^^^^^^^^^^^^^
  File "C:\Users\RJ EMPIRE\Desktop\Django\FundooNotes\Notes\serializers.py", line 64, in get_collaborator
    collaborator = CustomUser.objects.filter(id=data).first()
                   ^^^^^^^^^^^^^^^^^^^^^^^^^^^^^^^^^^
  File "C:\Users\RJ EMPIRE\Desktop\env\env03\Lib\site-packages\django\db\models\manager.py", line 85, in manager_method
    return getattr(self.get_queryset(), name)(*args, **kwargs)
           ^^^^^^^^^^^^^^^^^^^^^^^^^^^^^^^^^^^^^^^^^^^^^^^^^^^
  File "C:\Users\RJ EMPIRE\Desktop\env\env03\Lib\site-packages\django\db\models\query.py", line 1421, in filter
    return self._filter_or_exclude(False, args, kwargs)
           ^^^^^^^^^^^^^^^^^^^^^^^^^^^^^^^^^^^^^^^^^^^^
  File "C:\Users\RJ EMPIRE\Desktop\env\env03\Lib\site-packages\django\db\models\query.py", line 1439, in _filter_or_exclude
    clone._filter_or_exclude_inplace(negate, args, kwargs)
  File "C:\Users\RJ EMPIRE\Desktop\env\env03\Lib\site-packages\django\db\models\query.py", line 1446, in _filter_or_exclude_inplace
    self._query.add_q(Q(*args, **kwargs))
  File "C:\Users\RJ EMPIRE\Desktop\env\env03\Lib\site-packages\django\db\models\sql\query.py", line 1532, in add_q
    clause, _ = self._add_q(q_object, self.used_aliases)
                ^^^^^^^^^^^^^^^^^^^^^^^^^^^^^^^^^^^^^^^^
  File "C:\Users\RJ EMPIRE\Desktop\env\env03\Lib\site-packages\django\db\models\sql\query.py", line 1562, in _add_q
    child_clause, needed_inner = self.build_filter(
                                 ^^^^^^^^^^^^^^^^^^
  File "C:\Users\RJ EMPIRE\Desktop\env\env03\Lib\site-packages\django\db\models\sql\query.py", line 1478, in build_filter
    condition = self.build_lookup(lookups, col, value)
                ^^^^^^^^^^^^^^^^^^^^^^^^^^^^^^^^^^^^^^
  File "C:\Users\RJ EMPIRE\Desktop\env\env03\Lib\site-packages\django\db\models\sql\query.py", line 1303, in build_lookup
    lookup = lookup_class(lhs, rhs)
             ^^^^^^^^^^^^^^^^^^^^^^
  File "C:\Users\RJ EMPIRE\Desktop\env\env03\Lib\site-packages\django\db\models\lookups.py", line 27, in __init__
    self.rhs = self.get_prep_lookup()
               ^^^^^^^^^^^^^^^^^^^^^^
  File "C:\Users\RJ EMPIRE\Desktop\env\env03\Lib\site-packages\django\db\models\lookups.py", line 341, in get_prep_lookup
    return super().get_prep_lookup()
           ^^^^^^^^^^^^^^^^^^^^^^^^^
  File "C:\Users\RJ EMPIRE\Desktop\env\env03\Lib\site-packages\django\db\models\lookups.py", line 85, in get_prep_lookup
    return self.lhs.output_field.get_prep_value(self.rhs)
           ^^^^^^^^^^^^^^^^^^^^^^^^^^^^^^^^^^^^^^^^^^^^^^
  File "C:\Users\RJ EMPIRE\Desktop\env\env03\Lib\site-packages\django\db\models\fields\__init__.py", line 2020, in get_prep_value
    raise e.__class__(
ValueError: Field 'id' expected a number but got '['.
03/06/2023 12:22:35 PM : logging_confiq.logger : 
Traceback (most recent call last):
  File "C:\Users\RJ EMPIRE\Desktop\Django\FundooNotes\Notes\views.py", line 30, in post
    serializer.save()
  File "C:\Users\RJ EMPIRE\Desktop\env\env03\Lib\site-packages\rest_framework\serializers.py", line 212, in save
    self.instance = self.create(validated_data)
                    ^^^^^^^^^^^^^^^^^^^^^^^^^^^
  File "C:\Users\RJ EMPIRE\Desktop\Django\FundooNotes\Notes\serializers.py", line 29, in create
    collaborators = self.get_collaborator(collaborator_data)
                    ^^^^^^^^^^^^^^^^^^^^^^^^^^^^^^^^^^^^^^^^
  File "C:\Users\RJ EMPIRE\Desktop\Django\FundooNotes\Notes\serializers.py", line 55, in get_collaborator
    if data.isdigit():  # If input is user_id
       ^^^^^^^^^^^^
AttributeError: 'int' object has no attribute 'isdigit'
03/06/2023 12:22:35 PM : logging_confiq.logger : 
Traceback (most recent call last):
  File "C:\Users\RJ EMPIRE\Desktop\Django\FundooNotes\Notes\views.py", line 30, in post
    serializer.save()
  File "C:\Users\RJ EMPIRE\Desktop\env\env03\Lib\site-packages\rest_framework\serializers.py", line 212, in save
    self.instance = self.create(validated_data)
                    ^^^^^^^^^^^^^^^^^^^^^^^^^^^
  File "C:\Users\RJ EMPIRE\Desktop\Django\FundooNotes\Notes\serializers.py", line 29, in create
    collaborators = self.get_collaborator(collaborator_data)
                    ^^^^^^^^^^^^^^^^^^^^^^^^^^^^^^^^^^^^^^^^
  File "C:\Users\RJ EMPIRE\Desktop\Django\FundooNotes\Notes\serializers.py", line 55, in get_collaborator
    if data.isdigit():  # If input is user_id
       ^^^^^^^^^^^^
AttributeError: 'int' object has no attribute 'isdigit'
03/06/2023 01:27:22 PM : logging_confiq.logger : 
Traceback (most recent call last):
  File "C:\Users\RJ EMPIRE\Desktop\env\env03\Lib\site-packages\django\db\models\fields\__init__.py", line 2018, in get_prep_value
    return int(value)
           ^^^^^^^^^^
TypeError: int() argument must be a string, a bytes-like object or a real number, not 'QuerySet'

The above exception was the direct cause of the following exception:

Traceback (most recent call last):
  File "C:\Users\RJ EMPIRE\Desktop\Django\FundooNotes\Notes\views.py", line 30, in post
    serializer.save()
  File "C:\Users\RJ EMPIRE\Desktop\env\env03\Lib\site-packages\rest_framework\serializers.py", line 212, in save
    self.instance = self.create(validated_data)
                    ^^^^^^^^^^^^^^^^^^^^^^^^^^^
  File "C:\Users\RJ EMPIRE\Desktop\Django\FundooNotes\Notes\serializers.py", line 38, in create
    notes.collaborator.add(*collaborators)
  File "C:\Users\RJ EMPIRE\Desktop\env\env03\Lib\site-packages\django\db\models\fields\related_descriptors.py", line 1087, in add
    self._add_items(
  File "C:\Users\RJ EMPIRE\Desktop\env\env03\Lib\site-packages\django\db\models\fields\related_descriptors.py", line 1323, in _add_items
    target_ids = self._get_target_ids(target_field_name, objs)
                 ^^^^^^^^^^^^^^^^^^^^^^^^^^^^^^^^^^^^^^^^^^^^^
  File "C:\Users\RJ EMPIRE\Desktop\env\env03\Lib\site-packages\django\db\models\fields\related_descriptors.py", line 1257, in _get_target_ids
    target_ids.add(target_field.get_prep_value(obj))
                   ^^^^^^^^^^^^^^^^^^^^^^^^^^^^^^^^
  File "C:\Users\RJ EMPIRE\Desktop\env\env03\Lib\site-packages\django\db\models\fields\related.py", line 1152, in get_prep_value
    return self.target_field.get_prep_value(value)
           ^^^^^^^^^^^^^^^^^^^^^^^^^^^^^^^^^^^^^^^
  File "C:\Users\RJ EMPIRE\Desktop\env\env03\Lib\site-packages\django\db\models\fields\__init__.py", line 2020, in get_prep_value
    raise e.__class__(
TypeError: Field 'id' expected a number but got <QuerySet [<CustomUser: suraj>]>.
03/06/2023 01:27:22 PM : logging_confiq.logger : 
Traceback (most recent call last):
  File "C:\Users\RJ EMPIRE\Desktop\env\env03\Lib\site-packages\django\db\models\fields\__init__.py", line 2018, in get_prep_value
    return int(value)
           ^^^^^^^^^^
TypeError: int() argument must be a string, a bytes-like object or a real number, not 'QuerySet'

The above exception was the direct cause of the following exception:

Traceback (most recent call last):
  File "C:\Users\RJ EMPIRE\Desktop\Django\FundooNotes\Notes\views.py", line 30, in post
    serializer.save()
  File "C:\Users\RJ EMPIRE\Desktop\env\env03\Lib\site-packages\rest_framework\serializers.py", line 212, in save
    self.instance = self.create(validated_data)
                    ^^^^^^^^^^^^^^^^^^^^^^^^^^^
  File "C:\Users\RJ EMPIRE\Desktop\Django\FundooNotes\Notes\serializers.py", line 38, in create
    notes.collaborator.add(*collaborators)
  File "C:\Users\RJ EMPIRE\Desktop\env\env03\Lib\site-packages\django\db\models\fields\related_descriptors.py", line 1087, in add
    self._add_items(
  File "C:\Users\RJ EMPIRE\Desktop\env\env03\Lib\site-packages\django\db\models\fields\related_descriptors.py", line 1323, in _add_items
    target_ids = self._get_target_ids(target_field_name, objs)
                 ^^^^^^^^^^^^^^^^^^^^^^^^^^^^^^^^^^^^^^^^^^^^^
  File "C:\Users\RJ EMPIRE\Desktop\env\env03\Lib\site-packages\django\db\models\fields\related_descriptors.py", line 1257, in _get_target_ids
    target_ids.add(target_field.get_prep_value(obj))
                   ^^^^^^^^^^^^^^^^^^^^^^^^^^^^^^^^
  File "C:\Users\RJ EMPIRE\Desktop\env\env03\Lib\site-packages\django\db\models\fields\related.py", line 1152, in get_prep_value
    return self.target_field.get_prep_value(value)
           ^^^^^^^^^^^^^^^^^^^^^^^^^^^^^^^^^^^^^^^
  File "C:\Users\RJ EMPIRE\Desktop\env\env03\Lib\site-packages\django\db\models\fields\__init__.py", line 2020, in get_prep_value
    raise e.__class__(
TypeError: Field 'id' expected a number but got <QuerySet [<CustomUser: suraj>]>.
03/06/2023 01:31:55 PM : logging_confiq.logger : 
Traceback (most recent call last):
  File "C:\Users\RJ EMPIRE\Desktop\Django\FundooNotes\Notes\views.py", line 30, in post
    serializer.save()
  File "C:\Users\RJ EMPIRE\Desktop\env\env03\Lib\site-packages\rest_framework\serializers.py", line 212, in save
    self.instance = self.create(validated_data)
                    ^^^^^^^^^^^^^^^^^^^^^^^^^^^
  File "C:\Users\RJ EMPIRE\Desktop\Django\FundooNotes\Notes\serializers.py", line 29, in create
    collaborators = self.get_collaborator(collaborator_data)
                    ^^^^^^^^^^^^^^^^^^^^^^^^^^^^^^^^^^^^^^^^
  File "C:\Users\RJ EMPIRE\Desktop\Django\FundooNotes\Notes\serializers.py", line 69, in get_collaborator
    collaborator_id = collaborator.id
                      ^^^^^^^^^^^^^^^
AttributeError: 'QuerySet' object has no attribute 'id'
03/06/2023 01:31:55 PM : logging_confiq.logger : 
Traceback (most recent call last):
  File "C:\Users\RJ EMPIRE\Desktop\Django\FundooNotes\Notes\views.py", line 30, in post
    serializer.save()
  File "C:\Users\RJ EMPIRE\Desktop\env\env03\Lib\site-packages\rest_framework\serializers.py", line 212, in save
    self.instance = self.create(validated_data)
                    ^^^^^^^^^^^^^^^^^^^^^^^^^^^
  File "C:\Users\RJ EMPIRE\Desktop\Django\FundooNotes\Notes\serializers.py", line 29, in create
    collaborators = self.get_collaborator(collaborator_data)
                    ^^^^^^^^^^^^^^^^^^^^^^^^^^^^^^^^^^^^^^^^
  File "C:\Users\RJ EMPIRE\Desktop\Django\FundooNotes\Notes\serializers.py", line 69, in get_collaborator
    collaborator_id = collaborator.id
                      ^^^^^^^^^^^^^^^
AttributeError: 'QuerySet' object has no attribute 'id'
03/06/2023 02:05:23 PM : logging_confiq.logger : 
Traceback (most recent call last):
  File "C:\Users\RJ EMPIRE\Desktop\Django\FundooNotes\Notes\views.py", line 230, in post
    collaborator = get_collaborator(collaborator_data)
                   ^^^^^^^^^^^^^^^^^^^^^^^^^^^^^^^^^^^
TypeError: get_collaborator() missing 1 required positional argument: 'collaborator_data'
03/06/2023 02:05:23 PM : logging_confiq.logger : 
Traceback (most recent call last):
  File "C:\Users\RJ EMPIRE\Desktop\Django\FundooNotes\Notes\views.py", line 230, in post
    collaborator = get_collaborator(collaborator_data)
                   ^^^^^^^^^^^^^^^^^^^^^^^^^^^^^^^^^^^
TypeError: get_collaborator() missing 1 required positional argument: 'collaborator_data'
03/06/2023 02:07:16 PM : logging_confiq.logger : 
Traceback (most recent call last):
  File "C:\Users\RJ EMPIRE\Desktop\env\env03\Lib\site-packages\django\db\backends\utils.py", line 89, in _execute
    return self.cursor.execute(sql, params)
           ^^^^^^^^^^^^^^^^^^^^^^^^^^^^^^^^
psycopg2.errors.NotNullViolation: null value in column "customuser_id" of relation "Notes_notes_collaborator" violates not-null constraint
DETAIL:  Failing row contains (31, 203, null).


The above exception was the direct cause of the following exception:

Traceback (most recent call last):
  File "C:\Users\RJ EMPIRE\Desktop\Django\FundooNotes\Notes\views.py", line 234, in post
    note.collaborator.add(collaborator)
  File "C:\Users\RJ EMPIRE\Desktop\env\env03\Lib\site-packages\django\db\models\fields\related_descriptors.py", line 1087, in add
    self._add_items(
  File "C:\Users\RJ EMPIRE\Desktop\env\env03\Lib\site-packages\django\db\models\fields\related_descriptors.py", line 1329, in _add_items
    self.through._default_manager.using(db).bulk_create(
  File "C:\Users\RJ EMPIRE\Desktop\env\env03\Lib\site-packages\django\db\models\query.py", line 816, in bulk_create
    returned_columns = self._batched_insert(
                       ^^^^^^^^^^^^^^^^^^^^^
  File "C:\Users\RJ EMPIRE\Desktop\env\env03\Lib\site-packages\django\db\models\query.py", line 1825, in _batched_insert
    self._insert(
  File "C:\Users\RJ EMPIRE\Desktop\env\env03\Lib\site-packages\django\db\models\query.py", line 1791, in _insert
    return query.get_compiler(using=using).execute_sql(returning_fields)
           ^^^^^^^^^^^^^^^^^^^^^^^^^^^^^^^^^^^^^^^^^^^^^^^^^^^^^^^^^^^^^
  File "C:\Users\RJ EMPIRE\Desktop\env\env03\Lib\site-packages\django\db\models\sql\compiler.py", line 1660, in execute_sql
    cursor.execute(sql, params)
  File "C:\Users\RJ EMPIRE\Desktop\env\env03\Lib\site-packages\django\db\backends\utils.py", line 103, in execute
    return super().execute(sql, params)
           ^^^^^^^^^^^^^^^^^^^^^^^^^^^^
  File "C:\Users\RJ EMPIRE\Desktop\env\env03\Lib\site-packages\django\db\backends\utils.py", line 67, in execute
    return self._execute_with_wrappers(
           ^^^^^^^^^^^^^^^^^^^^^^^^^^^^
  File "C:\Users\RJ EMPIRE\Desktop\env\env03\Lib\site-packages\django\db\backends\utils.py", line 80, in _execute_with_wrappers
    return executor(sql, params, many, context)
           ^^^^^^^^^^^^^^^^^^^^^^^^^^^^^^^^^^^^
  File "C:\Users\RJ EMPIRE\Desktop\env\env03\Lib\site-packages\django\db\backends\utils.py", line 84, in _execute
    with self.db.wrap_database_errors:
  File "C:\Users\RJ EMPIRE\Desktop\env\env03\Lib\site-packages\django\db\utils.py", line 91, in __exit__
    raise dj_exc_value.with_traceback(traceback) from exc_value
  File "C:\Users\RJ EMPIRE\Desktop\env\env03\Lib\site-packages\django\db\backends\utils.py", line 89, in _execute
    return self.cursor.execute(sql, params)
           ^^^^^^^^^^^^^^^^^^^^^^^^^^^^^^^^
django.db.utils.IntegrityError: null value in column "customuser_id" of relation "Notes_notes_collaborator" violates not-null constraint
DETAIL:  Failing row contains (31, 203, null).

03/06/2023 02:07:16 PM : logging_confiq.logger : 
Traceback (most recent call last):
  File "C:\Users\RJ EMPIRE\Desktop\env\env03\Lib\site-packages\django\db\backends\utils.py", line 89, in _execute
    return self.cursor.execute(sql, params)
           ^^^^^^^^^^^^^^^^^^^^^^^^^^^^^^^^
psycopg2.errors.NotNullViolation: null value in column "customuser_id" of relation "Notes_notes_collaborator" violates not-null constraint
DETAIL:  Failing row contains (31, 203, null).


The above exception was the direct cause of the following exception:

Traceback (most recent call last):
  File "C:\Users\RJ EMPIRE\Desktop\Django\FundooNotes\Notes\views.py", line 234, in post
    note.collaborator.add(collaborator)
  File "C:\Users\RJ EMPIRE\Desktop\env\env03\Lib\site-packages\django\db\models\fields\related_descriptors.py", line 1087, in add
    self._add_items(
  File "C:\Users\RJ EMPIRE\Desktop\env\env03\Lib\site-packages\django\db\models\fields\related_descriptors.py", line 1329, in _add_items
    self.through._default_manager.using(db).bulk_create(
  File "C:\Users\RJ EMPIRE\Desktop\env\env03\Lib\site-packages\django\db\models\query.py", line 816, in bulk_create
    returned_columns = self._batched_insert(
                       ^^^^^^^^^^^^^^^^^^^^^
  File "C:\Users\RJ EMPIRE\Desktop\env\env03\Lib\site-packages\django\db\models\query.py", line 1825, in _batched_insert
    self._insert(
  File "C:\Users\RJ EMPIRE\Desktop\env\env03\Lib\site-packages\django\db\models\query.py", line 1791, in _insert
    return query.get_compiler(using=using).execute_sql(returning_fields)
           ^^^^^^^^^^^^^^^^^^^^^^^^^^^^^^^^^^^^^^^^^^^^^^^^^^^^^^^^^^^^^
  File "C:\Users\RJ EMPIRE\Desktop\env\env03\Lib\site-packages\django\db\models\sql\compiler.py", line 1660, in execute_sql
    cursor.execute(sql, params)
  File "C:\Users\RJ EMPIRE\Desktop\env\env03\Lib\site-packages\django\db\backends\utils.py", line 103, in execute
    return super().execute(sql, params)
           ^^^^^^^^^^^^^^^^^^^^^^^^^^^^
  File "C:\Users\RJ EMPIRE\Desktop\env\env03\Lib\site-packages\django\db\backends\utils.py", line 67, in execute
    return self._execute_with_wrappers(
           ^^^^^^^^^^^^^^^^^^^^^^^^^^^^
  File "C:\Users\RJ EMPIRE\Desktop\env\env03\Lib\site-packages\django\db\backends\utils.py", line 80, in _execute_with_wrappers
    return executor(sql, params, many, context)
           ^^^^^^^^^^^^^^^^^^^^^^^^^^^^^^^^^^^^
  File "C:\Users\RJ EMPIRE\Desktop\env\env03\Lib\site-packages\django\db\backends\utils.py", line 84, in _execute
    with self.db.wrap_database_errors:
  File "C:\Users\RJ EMPIRE\Desktop\env\env03\Lib\site-packages\django\db\utils.py", line 91, in __exit__
    raise dj_exc_value.with_traceback(traceback) from exc_value
  File "C:\Users\RJ EMPIRE\Desktop\env\env03\Lib\site-packages\django\db\backends\utils.py", line 89, in _execute
    return self.cursor.execute(sql, params)
           ^^^^^^^^^^^^^^^^^^^^^^^^^^^^^^^^
django.db.utils.IntegrityError: null value in column "customuser_id" of relation "Notes_notes_collaborator" violates not-null constraint
DETAIL:  Failing row contains (31, 203, null).

03/06/2023 04:29:35 PM : logging_confiq.logger : 
Traceback (most recent call last):
  File "C:\Users\RJ EMPIRE\Desktop\Django\FundooNotes\Notes\views.py", line 218, in post
    note = Notes.objects.get(pk=request.data.get('note_id'))
           ^^^^^^^^^^^^^^^^^^^^^^^^^^^^^^^^^^^^^^^^^^^^^^^^^
  File "C:\Users\RJ EMPIRE\Desktop\env\env03\Lib\site-packages\django\db\models\manager.py", line 85, in manager_method
    return getattr(self.get_queryset(), name)(*args, **kwargs)
           ^^^^^^^^^^^^^^^^^^^^^^^^^^^^^^^^^^^^^^^^^^^^^^^^^^^
  File "C:\Users\RJ EMPIRE\Desktop\env\env03\Lib\site-packages\django\db\models\query.py", line 650, in get
    raise self.model.DoesNotExist(
Notes.models.Notes.DoesNotExist: Notes matching query does not exist.
03/06/2023 04:29:35 PM : logging_confiq.logger : 
Traceback (most recent call last):
  File "C:\Users\RJ EMPIRE\Desktop\Django\FundooNotes\Notes\views.py", line 218, in post
    note = Notes.objects.get(pk=request.data.get('note_id'))
           ^^^^^^^^^^^^^^^^^^^^^^^^^^^^^^^^^^^^^^^^^^^^^^^^^
  File "C:\Users\RJ EMPIRE\Desktop\env\env03\Lib\site-packages\django\db\models\manager.py", line 85, in manager_method
    return getattr(self.get_queryset(), name)(*args, **kwargs)
           ^^^^^^^^^^^^^^^^^^^^^^^^^^^^^^^^^^^^^^^^^^^^^^^^^^^
  File "C:\Users\RJ EMPIRE\Desktop\env\env03\Lib\site-packages\django\db\models\query.py", line 650, in get
    raise self.model.DoesNotExist(
Notes.models.Notes.DoesNotExist: Notes matching query does not exist.
03/06/2023 04:29:46 PM : logging_confiq.logger : 
Traceback (most recent call last):
  File "C:\Users\RJ EMPIRE\Desktop\Django\FundooNotes\Notes\views.py", line 230, in post
    return Response({'message': f'Added collaborator with id {collaborator.id} to note with id {note_id}'},
                                                                                                ^^^^^^^
NameError: name 'note_id' is not defined
03/06/2023 04:29:46 PM : logging_confiq.logger : 
Traceback (most recent call last):
  File "C:\Users\RJ EMPIRE\Desktop\Django\FundooNotes\Notes\views.py", line 230, in post
    return Response({'message': f'Added collaborator with id {collaborator.id} to note with id {note_id}'},
                                                                                                ^^^^^^^
NameError: name 'note_id' is not defined
03/06/2023 04:36:36 PM : logging_confiq.logger : 
Traceback (most recent call last):
  File "C:\Users\RJ EMPIRE\Desktop\Django\FundooNotes\Notes\views.py", line 218, in post
    note = Notes.objects.get(pk=request.POST.get('note_id'))
           ^^^^^^^^^^^^^^^^^^^^^^^^^^^^^^^^^^^^^^^^^^^^^^^^^
  File "C:\Users\RJ EMPIRE\Desktop\env\env03\Lib\site-packages\django\db\models\manager.py", line 85, in manager_method
    return getattr(self.get_queryset(), name)(*args, **kwargs)
           ^^^^^^^^^^^^^^^^^^^^^^^^^^^^^^^^^^^^^^^^^^^^^^^^^^^
  File "C:\Users\RJ EMPIRE\Desktop\env\env03\Lib\site-packages\django\db\models\query.py", line 650, in get
    raise self.model.DoesNotExist(
Notes.models.Notes.DoesNotExist: Notes matching query does not exist.
03/06/2023 04:36:36 PM : logging_confiq.logger : 
Traceback (most recent call last):
  File "C:\Users\RJ EMPIRE\Desktop\Django\FundooNotes\Notes\views.py", line 218, in post
    note = Notes.objects.get(pk=request.POST.get('note_id'))
           ^^^^^^^^^^^^^^^^^^^^^^^^^^^^^^^^^^^^^^^^^^^^^^^^^
  File "C:\Users\RJ EMPIRE\Desktop\env\env03\Lib\site-packages\django\db\models\manager.py", line 85, in manager_method
    return getattr(self.get_queryset(), name)(*args, **kwargs)
           ^^^^^^^^^^^^^^^^^^^^^^^^^^^^^^^^^^^^^^^^^^^^^^^^^^^
  File "C:\Users\RJ EMPIRE\Desktop\env\env03\Lib\site-packages\django\db\models\query.py", line 650, in get
    raise self.model.DoesNotExist(
Notes.models.Notes.DoesNotExist: Notes matching query does not exist.
03/06/2023 04:42:19 PM : logging_confiq.logger : 
Traceback (most recent call last):
  File "C:\Users\RJ EMPIRE\Desktop\Django\FundooNotes\Notes\views.py", line 230, in post
    return Response({'message': f'Added collaborator with id {collaborator.id} to note with id {note_id}'},
                                                                                                ^^^^^^^
NameError: name 'note_id' is not defined
03/06/2023 04:42:19 PM : logging_confiq.logger : 
Traceback (most recent call last):
  File "C:\Users\RJ EMPIRE\Desktop\Django\FundooNotes\Notes\views.py", line 230, in post
    return Response({'message': f'Added collaborator with id {collaborator.id} to note with id {note_id}'},
                                                                                                ^^^^^^^
NameError: name 'note_id' is not defined
03/06/2023 05:18:41 PM : logging_confiq.logger : 
Traceback (most recent call last):
  File "C:\Users\RJ EMPIRE\Desktop\env\env03\Lib\site-packages\django\db\models\fields\__init__.py", line 2018, in get_prep_value
    return int(value)
           ^^^^^^^^^^
ValueError: invalid literal for int() with base 10: 'milan@gmail.com'

The above exception was the direct cause of the following exception:

Traceback (most recent call last):
  File "C:\Users\RJ EMPIRE\Desktop\Django\FundooNotes\Notes\views.py", line 241, in delete
    user = CustomUser.objects.get(pk=user_id)
           ^^^^^^^^^^^^^^^^^^^^^^^^^^^^^^^^^^
  File "C:\Users\RJ EMPIRE\Desktop\env\env03\Lib\site-packages\django\db\models\manager.py", line 85, in manager_method
    return getattr(self.get_queryset(), name)(*args, **kwargs)
           ^^^^^^^^^^^^^^^^^^^^^^^^^^^^^^^^^^^^^^^^^^^^^^^^^^^
  File "C:\Users\RJ EMPIRE\Desktop\env\env03\Lib\site-packages\django\db\models\query.py", line 636, in get
    clone = self._chain() if self.query.combinator else self.filter(*args, **kwargs)
                                                        ^^^^^^^^^^^^^^^^^^^^^^^^^^^^
  File "C:\Users\RJ EMPIRE\Desktop\env\env03\Lib\site-packages\django\db\models\query.py", line 1421, in filter
    return self._filter_or_exclude(False, args, kwargs)
           ^^^^^^^^^^^^^^^^^^^^^^^^^^^^^^^^^^^^^^^^^^^^
  File "C:\Users\RJ EMPIRE\Desktop\env\env03\Lib\site-packages\django\db\models\query.py", line 1439, in _filter_or_exclude
    clone._filter_or_exclude_inplace(negate, args, kwargs)
  File "C:\Users\RJ EMPIRE\Desktop\env\env03\Lib\site-packages\django\db\models\query.py", line 1446, in _filter_or_exclude_inplace
    self._query.add_q(Q(*args, **kwargs))
  File "C:\Users\RJ EMPIRE\Desktop\env\env03\Lib\site-packages\django\db\models\sql\query.py", line 1532, in add_q
    clause, _ = self._add_q(q_object, self.used_aliases)
                ^^^^^^^^^^^^^^^^^^^^^^^^^^^^^^^^^^^^^^^^
  File "C:\Users\RJ EMPIRE\Desktop\env\env03\Lib\site-packages\django\db\models\sql\query.py", line 1562, in _add_q
    child_clause, needed_inner = self.build_filter(
                                 ^^^^^^^^^^^^^^^^^^
  File "C:\Users\RJ EMPIRE\Desktop\env\env03\Lib\site-packages\django\db\models\sql\query.py", line 1478, in build_filter
    condition = self.build_lookup(lookups, col, value)
                ^^^^^^^^^^^^^^^^^^^^^^^^^^^^^^^^^^^^^^
  File "C:\Users\RJ EMPIRE\Desktop\env\env03\Lib\site-packages\django\db\models\sql\query.py", line 1303, in build_lookup
    lookup = lookup_class(lhs, rhs)
             ^^^^^^^^^^^^^^^^^^^^^^
  File "C:\Users\RJ EMPIRE\Desktop\env\env03\Lib\site-packages\django\db\models\lookups.py", line 27, in __init__
    self.rhs = self.get_prep_lookup()
               ^^^^^^^^^^^^^^^^^^^^^^
  File "C:\Users\RJ EMPIRE\Desktop\env\env03\Lib\site-packages\django\db\models\lookups.py", line 341, in get_prep_lookup
    return super().get_prep_lookup()
           ^^^^^^^^^^^^^^^^^^^^^^^^^
  File "C:\Users\RJ EMPIRE\Desktop\env\env03\Lib\site-packages\django\db\models\lookups.py", line 85, in get_prep_lookup
    return self.lhs.output_field.get_prep_value(self.rhs)
           ^^^^^^^^^^^^^^^^^^^^^^^^^^^^^^^^^^^^^^^^^^^^^^
  File "C:\Users\RJ EMPIRE\Desktop\env\env03\Lib\site-packages\django\db\models\fields\__init__.py", line 2020, in get_prep_value
    raise e.__class__(
ValueError: Field 'id' expected a number but got 'milan@gmail.com'.
03/06/2023 05:18:41 PM : logging_confiq.logger : 
Traceback (most recent call last):
  File "C:\Users\RJ EMPIRE\Desktop\env\env03\Lib\site-packages\django\db\models\fields\__init__.py", line 2018, in get_prep_value
    return int(value)
           ^^^^^^^^^^
ValueError: invalid literal for int() with base 10: 'milan@gmail.com'

The above exception was the direct cause of the following exception:

Traceback (most recent call last):
  File "C:\Users\RJ EMPIRE\Desktop\Django\FundooNotes\Notes\views.py", line 241, in delete
    user = CustomUser.objects.get(pk=user_id)
           ^^^^^^^^^^^^^^^^^^^^^^^^^^^^^^^^^^
  File "C:\Users\RJ EMPIRE\Desktop\env\env03\Lib\site-packages\django\db\models\manager.py", line 85, in manager_method
    return getattr(self.get_queryset(), name)(*args, **kwargs)
           ^^^^^^^^^^^^^^^^^^^^^^^^^^^^^^^^^^^^^^^^^^^^^^^^^^^
  File "C:\Users\RJ EMPIRE\Desktop\env\env03\Lib\site-packages\django\db\models\query.py", line 636, in get
    clone = self._chain() if self.query.combinator else self.filter(*args, **kwargs)
                                                        ^^^^^^^^^^^^^^^^^^^^^^^^^^^^
  File "C:\Users\RJ EMPIRE\Desktop\env\env03\Lib\site-packages\django\db\models\query.py", line 1421, in filter
    return self._filter_or_exclude(False, args, kwargs)
           ^^^^^^^^^^^^^^^^^^^^^^^^^^^^^^^^^^^^^^^^^^^^
  File "C:\Users\RJ EMPIRE\Desktop\env\env03\Lib\site-packages\django\db\models\query.py", line 1439, in _filter_or_exclude
    clone._filter_or_exclude_inplace(negate, args, kwargs)
  File "C:\Users\RJ EMPIRE\Desktop\env\env03\Lib\site-packages\django\db\models\query.py", line 1446, in _filter_or_exclude_inplace
    self._query.add_q(Q(*args, **kwargs))
  File "C:\Users\RJ EMPIRE\Desktop\env\env03\Lib\site-packages\django\db\models\sql\query.py", line 1532, in add_q
    clause, _ = self._add_q(q_object, self.used_aliases)
                ^^^^^^^^^^^^^^^^^^^^^^^^^^^^^^^^^^^^^^^^
  File "C:\Users\RJ EMPIRE\Desktop\env\env03\Lib\site-packages\django\db\models\sql\query.py", line 1562, in _add_q
    child_clause, needed_inner = self.build_filter(
                                 ^^^^^^^^^^^^^^^^^^
  File "C:\Users\RJ EMPIRE\Desktop\env\env03\Lib\site-packages\django\db\models\sql\query.py", line 1478, in build_filter
    condition = self.build_lookup(lookups, col, value)
                ^^^^^^^^^^^^^^^^^^^^^^^^^^^^^^^^^^^^^^
  File "C:\Users\RJ EMPIRE\Desktop\env\env03\Lib\site-packages\django\db\models\sql\query.py", line 1303, in build_lookup
    lookup = lookup_class(lhs, rhs)
             ^^^^^^^^^^^^^^^^^^^^^^
  File "C:\Users\RJ EMPIRE\Desktop\env\env03\Lib\site-packages\django\db\models\lookups.py", line 27, in __init__
    self.rhs = self.get_prep_lookup()
               ^^^^^^^^^^^^^^^^^^^^^^
  File "C:\Users\RJ EMPIRE\Desktop\env\env03\Lib\site-packages\django\db\models\lookups.py", line 341, in get_prep_lookup
    return super().get_prep_lookup()
           ^^^^^^^^^^^^^^^^^^^^^^^^^
  File "C:\Users\RJ EMPIRE\Desktop\env\env03\Lib\site-packages\django\db\models\lookups.py", line 85, in get_prep_lookup
    return self.lhs.output_field.get_prep_value(self.rhs)
           ^^^^^^^^^^^^^^^^^^^^^^^^^^^^^^^^^^^^^^^^^^^^^^
  File "C:\Users\RJ EMPIRE\Desktop\env\env03\Lib\site-packages\django\db\models\fields\__init__.py", line 2020, in get_prep_value
    raise e.__class__(
ValueError: Field 'id' expected a number but got 'milan@gmail.com'.
03/06/2023 05:46:35 PM : logging_confiq.logger : 
Traceback (most recent call last):
  File "C:\Users\RJ EMPIRE\Desktop\Django\FundooNotes\Notes\views.py", line 248, in delete
    {'message':f'Successfully removed collaborator with {collaborator.data} from note with id {note_id}'},
                                                         ^^^^^^^^^^^^^^^^^
AttributeError: 'CustomUser' object has no attribute 'data'
03/06/2023 05:46:35 PM : logging_confiq.logger : 
Traceback (most recent call last):
  File "C:\Users\RJ EMPIRE\Desktop\Django\FundooNotes\Notes\views.py", line 248, in delete
    {'message':f'Successfully removed collaborator with {collaborator.data} from note with id {note_id}'},
                                                         ^^^^^^^^^^^^^^^^^
AttributeError: 'CustomUser' object has no attribute 'data'
03/06/2023 05:48:52 PM : logging_confiq.logger : 
Traceback (most recent call last):
  File "C:\Users\RJ EMPIRE\Desktop\Django\FundooNotes\Notes\views.py", line 244, in delete
    collaborator = get_collaborator(self, collaborator_data)
                   ^^^^^^^^^^^^^^^^^^^^^^^^^^^^^^^^^^^^^^^^^
  File "C:\Users\RJ EMPIRE\Desktop\Django\FundooNotes\Notes\serializers.py", line 44, in get_collaborator
    if collaborator_data.isdigit():  # If input is user_id
       ^^^^^^^^^^^^^^^^^^^^^^^^^
AttributeError: 'int' object has no attribute 'isdigit'
03/06/2023 05:48:52 PM : logging_confiq.logger : 
Traceback (most recent call last):
  File "C:\Users\RJ EMPIRE\Desktop\Django\FundooNotes\Notes\views.py", line 244, in delete
    collaborator = get_collaborator(self, collaborator_data)
                   ^^^^^^^^^^^^^^^^^^^^^^^^^^^^^^^^^^^^^^^^^
  File "C:\Users\RJ EMPIRE\Desktop\Django\FundooNotes\Notes\serializers.py", line 44, in get_collaborator
    if collaborator_data.isdigit():  # If input is user_id
       ^^^^^^^^^^^^^^^^^^^^^^^^^
AttributeError: 'int' object has no attribute 'isdigit'
03/06/2023 06:01:14 PM : logging_confiq.logger : 
Traceback (most recent call last):
  File "C:\Users\RJ EMPIRE\Desktop\Django\FundooNotes\Notes\views.py", line 244, in delete
    collaborator = get_collaborator(self, collaborator_data)
                   ^^^^^^^^^^^^^^^^^^^^^^^^^^^^^^^^^^^^^^^^^
  File "C:\Users\RJ EMPIRE\Desktop\Django\FundooNotes\Notes\serializers.py", line 44, in get_collaborator
    if collaborator_data.isdigit():  # If input is user_id
       ^^^^^^^^^^^^^^^^^^^^^^^^^
AttributeError: 'int' object has no attribute 'isdigit'
03/06/2023 06:01:14 PM : logging_confiq.logger : 
Traceback (most recent call last):
  File "C:\Users\RJ EMPIRE\Desktop\Django\FundooNotes\Notes\views.py", line 244, in delete
    collaborator = get_collaborator(self, collaborator_data)
                   ^^^^^^^^^^^^^^^^^^^^^^^^^^^^^^^^^^^^^^^^^
  File "C:\Users\RJ EMPIRE\Desktop\Django\FundooNotes\Notes\serializers.py", line 44, in get_collaborator
    if collaborator_data.isdigit():  # If input is user_id
       ^^^^^^^^^^^^^^^^^^^^^^^^^
AttributeError: 'int' object has no attribute 'isdigit'
03/06/2023 06:03:25 PM : logging_confiq.logger : 
Traceback (most recent call last):
  File "C:\Users\RJ EMPIRE\Desktop\Django\FundooNotes\Notes\views.py", line 244, in delete
    collaborator = get_collaborator(self, collaborator_data)
                   ^^^^^^^^^^^^^^^^^^^^^^^^^^^^^^^^^^^^^^^^^
  File "C:\Users\RJ EMPIRE\Desktop\Django\FundooNotes\Notes\serializers.py", line 44, in get_collaborator
    if collaborator_data.isdigit():  # If input is user_id
       ^^^^^^^^^^^^^^^^^^^^^^^^^
AttributeError: 'int' object has no attribute 'isdigit'
03/06/2023 06:03:25 PM : logging_confiq.logger : 
Traceback (most recent call last):
  File "C:\Users\RJ EMPIRE\Desktop\Django\FundooNotes\Notes\views.py", line 244, in delete
    collaborator = get_collaborator(self, collaborator_data)
                   ^^^^^^^^^^^^^^^^^^^^^^^^^^^^^^^^^^^^^^^^^
  File "C:\Users\RJ EMPIRE\Desktop\Django\FundooNotes\Notes\serializers.py", line 44, in get_collaborator
    if collaborator_data.isdigit():  # If input is user_id
       ^^^^^^^^^^^^^^^^^^^^^^^^^
AttributeError: 'int' object has no attribute 'isdigit'
03/06/2023 06:19:27 PM : logging_confiq.logger : 
Traceback (most recent call last):
  File "C:\Users\RJ EMPIRE\Desktop\Django\FundooNotes\Notes\views.py", line 223, in post
    collaborator = get_collaborator(self, collaborator_data)
                   ^^^^^^^^^^^^^^^^^^^^^^^^^^^^^^^^^^^^^^^^^
  File "C:\Users\RJ EMPIRE\Desktop\Django\FundooNotes\Notes\serializers.py", line 44, in get_collaborator
    if collaborator_data.isdigit():  # If input is user_id
       ^^^^^^^^^^^^^^^^^^^^^^^^^
AttributeError: 'int' object has no attribute 'isdigit'
03/06/2023 06:19:27 PM : logging_confiq.logger : 
Traceback (most recent call last):
  File "C:\Users\RJ EMPIRE\Desktop\Django\FundooNotes\Notes\views.py", line 223, in post
    collaborator = get_collaborator(self, collaborator_data)
                   ^^^^^^^^^^^^^^^^^^^^^^^^^^^^^^^^^^^^^^^^^
  File "C:\Users\RJ EMPIRE\Desktop\Django\FundooNotes\Notes\serializers.py", line 44, in get_collaborator
    if collaborator_data.isdigit():  # If input is user_id
       ^^^^^^^^^^^^^^^^^^^^^^^^^
AttributeError: 'int' object has no attribute 'isdigit'
03/06/2023 06:52:25 PM : logging_confiq.logger : 
Traceback (most recent call last):
  File "C:\Users\RJ EMPIRE\Desktop\Django\FundooNotes\Notes\views.py", line 31, in post
    serializer.save()
  File "C:\Users\RJ EMPIRE\Desktop\env\env03\Lib\site-packages\rest_framework\serializers.py", line 212, in save
    self.instance = self.create(validated_data)
                    ^^^^^^^^^^^^^^^^^^^^^^^^^^^
  File "C:\Users\RJ EMPIRE\Desktop\Django\FundooNotes\Notes\serializers.py", line 34, in create
    collaborators = [get_collaborator(data) for data in collaborator_data]
                    ^^^^^^^^^^^^^^^^^^^^^^^^^^^^^^^^^^^^^^^^^^^^^^^^^^^^^^
  File "C:\Users\RJ EMPIRE\Desktop\Django\FundooNotes\Notes\serializers.py", line 34, in <listcomp>
    collaborators = [get_collaborator(data) for data in collaborator_data]
                     ^^^^^^^^^^^^^^^^^^^^^^
TypeError: get_collaborator() missing 1 required positional argument: 'collaborator_data'
03/06/2023 06:52:25 PM : logging_confiq.logger : 
Traceback (most recent call last):
  File "C:\Users\RJ EMPIRE\Desktop\Django\FundooNotes\Notes\views.py", line 31, in post
    serializer.save()
  File "C:\Users\RJ EMPIRE\Desktop\env\env03\Lib\site-packages\rest_framework\serializers.py", line 212, in save
    self.instance = self.create(validated_data)
                    ^^^^^^^^^^^^^^^^^^^^^^^^^^^
  File "C:\Users\RJ EMPIRE\Desktop\Django\FundooNotes\Notes\serializers.py", line 34, in create
    collaborators = [get_collaborator(data) for data in collaborator_data]
                    ^^^^^^^^^^^^^^^^^^^^^^^^^^^^^^^^^^^^^^^^^^^^^^^^^^^^^^
  File "C:\Users\RJ EMPIRE\Desktop\Django\FundooNotes\Notes\serializers.py", line 34, in <listcomp>
    collaborators = [get_collaborator(data) for data in collaborator_data]
                     ^^^^^^^^^^^^^^^^^^^^^^
TypeError: get_collaborator() missing 1 required positional argument: 'collaborator_data'
03/07/2023 12:01:18 AM : logging_confiq.logger : 
Traceback (most recent call last):
  File "C:\Users\RJ EMPIRE\Desktop\Django\FundooNotes\Notes\views.py", line 191, in put
    notes = Notes.objects.get(id=note_id, user=request.user).first()
            ^^^^^^^^^^^^^^^^^^^^^^^^^^^^^^^^^^^^^^^^^^^^^^^^
  File "C:\Users\RJ EMPIRE\Desktop\env\env03\Lib\site-packages\django\db\models\manager.py", line 85, in manager_method
    return getattr(self.get_queryset(), name)(*args, **kwargs)
           ^^^^^^^^^^^^^^^^^^^^^^^^^^^^^^^^^^^^^^^^^^^^^^^^^^^
  File "C:\Users\RJ EMPIRE\Desktop\env\env03\Lib\site-packages\django\db\models\query.py", line 650, in get
    raise self.model.DoesNotExist(
Notes.models.Notes.DoesNotExist: Notes matching query does not exist.
03/07/2023 12:01:18 AM : logging_confiq.logger : 
Traceback (most recent call last):
  File "C:\Users\RJ EMPIRE\Desktop\Django\FundooNotes\Notes\views.py", line 191, in put
    notes = Notes.objects.get(id=note_id, user=request.user).first()
            ^^^^^^^^^^^^^^^^^^^^^^^^^^^^^^^^^^^^^^^^^^^^^^^^
  File "C:\Users\RJ EMPIRE\Desktop\env\env03\Lib\site-packages\django\db\models\manager.py", line 85, in manager_method
    return getattr(self.get_queryset(), name)(*args, **kwargs)
           ^^^^^^^^^^^^^^^^^^^^^^^^^^^^^^^^^^^^^^^^^^^^^^^^^^^
  File "C:\Users\RJ EMPIRE\Desktop\env\env03\Lib\site-packages\django\db\models\query.py", line 650, in get
    raise self.model.DoesNotExist(
Notes.models.Notes.DoesNotExist: Notes matching query does not exist.
03/07/2023 12:01:18 AM : logging_confiq.logger : 
Traceback (most recent call last):
  File "C:\Users\RJ EMPIRE\Desktop\Django\FundooNotes\Notes\views.py", line 191, in put
    notes = Notes.objects.get(id=note_id, user=request.user).first()
            ^^^^^^^^^^^^^^^^^^^^^^^^^^^^^^^^^^^^^^^^^^^^^^^^
  File "C:\Users\RJ EMPIRE\Desktop\env\env03\Lib\site-packages\django\db\models\manager.py", line 85, in manager_method
    return getattr(self.get_queryset(), name)(*args, **kwargs)
           ^^^^^^^^^^^^^^^^^^^^^^^^^^^^^^^^^^^^^^^^^^^^^^^^^^^
  File "C:\Users\RJ EMPIRE\Desktop\env\env03\Lib\site-packages\django\db\models\query.py", line 650, in get
    raise self.model.DoesNotExist(
Notes.models.Notes.DoesNotExist: Notes matching query does not exist.
03/07/2023 12:01:44 AM : logging_confiq.logger : 
Traceback (most recent call last):
  File "C:\Users\RJ EMPIRE\Desktop\Django\FundooNotes\Notes\views.py", line 191, in put
    notes = Notes.objects.get(id=note_id, user=request.user).first()
            ^^^^^^^^^^^^^^^^^^^^^^^^^^^^^^^^^^^^^^^^^^^^^^^^^^^^^^
AttributeError: 'Notes' object has no attribute 'first'
03/07/2023 12:01:44 AM : logging_confiq.logger : 
Traceback (most recent call last):
  File "C:\Users\RJ EMPIRE\Desktop\Django\FundooNotes\Notes\views.py", line 191, in put
    notes = Notes.objects.get(id=note_id, user=request.user).first()
            ^^^^^^^^^^^^^^^^^^^^^^^^^^^^^^^^^^^^^^^^^^^^^^^^^^^^^^
AttributeError: 'Notes' object has no attribute 'first'
03/07/2023 12:01:44 AM : logging_confiq.logger : 
Traceback (most recent call last):
  File "C:\Users\RJ EMPIRE\Desktop\Django\FundooNotes\Notes\views.py", line 191, in put
    notes = Notes.objects.get(id=note_id, user=request.user).first()
            ^^^^^^^^^^^^^^^^^^^^^^^^^^^^^^^^^^^^^^^^^^^^^^^^^^^^^^
AttributeError: 'Notes' object has no attribute 'first'
03/07/2023 12:47:27 AM : logging_confiq.logger : 
Traceback (most recent call last):
  File "C:\Users\RJ EMPIRE\Desktop\Django\FundooNotes\Notes\views.py", line 191, in put
    notes = Notes.objects.get(id=note_id, user=request.user)
            ^^^^^^^^^^^^^^^^^^^^^^^^^^^^^^^^^^^^^^^^^^^^^^^^
  File "C:\Users\RJ EMPIRE\Desktop\env\env03\Lib\site-packages\django\db\models\manager.py", line 85, in manager_method
    return getattr(self.get_queryset(), name)(*args, **kwargs)
           ^^^^^^^^^^^^^^^^^^^^^^^^^^^^^^^^^^^^^^^^^^^^^^^^^^^
  File "C:\Users\RJ EMPIRE\Desktop\env\env03\Lib\site-packages\django\db\models\query.py", line 650, in get
    raise self.model.DoesNotExist(
Notes.models.Notes.DoesNotExist: Notes matching query does not exist.
03/07/2023 12:47:27 AM : logging_confiq.logger : 
Traceback (most recent call last):
  File "C:\Users\RJ EMPIRE\Desktop\Django\FundooNotes\Notes\views.py", line 191, in put
    notes = Notes.objects.get(id=note_id, user=request.user)
            ^^^^^^^^^^^^^^^^^^^^^^^^^^^^^^^^^^^^^^^^^^^^^^^^
  File "C:\Users\RJ EMPIRE\Desktop\env\env03\Lib\site-packages\django\db\models\manager.py", line 85, in manager_method
    return getattr(self.get_queryset(), name)(*args, **kwargs)
           ^^^^^^^^^^^^^^^^^^^^^^^^^^^^^^^^^^^^^^^^^^^^^^^^^^^
  File "C:\Users\RJ EMPIRE\Desktop\env\env03\Lib\site-packages\django\db\models\query.py", line 650, in get
    raise self.model.DoesNotExist(
Notes.models.Notes.DoesNotExist: Notes matching query does not exist.
03/07/2023 12:47:27 AM : logging_confiq.logger : 
Traceback (most recent call last):
  File "C:\Users\RJ EMPIRE\Desktop\Django\FundooNotes\Notes\views.py", line 191, in put
    notes = Notes.objects.get(id=note_id, user=request.user)
            ^^^^^^^^^^^^^^^^^^^^^^^^^^^^^^^^^^^^^^^^^^^^^^^^
  File "C:\Users\RJ EMPIRE\Desktop\env\env03\Lib\site-packages\django\db\models\manager.py", line 85, in manager_method
    return getattr(self.get_queryset(), name)(*args, **kwargs)
           ^^^^^^^^^^^^^^^^^^^^^^^^^^^^^^^^^^^^^^^^^^^^^^^^^^^
  File "C:\Users\RJ EMPIRE\Desktop\env\env03\Lib\site-packages\django\db\models\query.py", line 650, in get
    raise self.model.DoesNotExist(
Notes.models.Notes.DoesNotExist: Notes matching query does not exist.
03/07/2023 12:49:24 AM : logging_confiq.logger : 
Traceback (most recent call last):
  File "C:\Users\RJ EMPIRE\Desktop\Django\FundooNotes\Notes\views.py", line 191, in put
    notes = Notes.objects.get(id=note_id, user=request.user)
            ^^^^^^^^^^^^^^^^^^^^^^^^^^^^^^^^^^^^^^^^^^^^^^^^
  File "C:\Users\RJ EMPIRE\Desktop\env\env03\Lib\site-packages\django\db\models\manager.py", line 85, in manager_method
    return getattr(self.get_queryset(), name)(*args, **kwargs)
           ^^^^^^^^^^^^^^^^^^^^^^^^^^^^^^^^^^^^^^^^^^^^^^^^^^^
  File "C:\Users\RJ EMPIRE\Desktop\env\env03\Lib\site-packages\django\db\models\query.py", line 650, in get
    raise self.model.DoesNotExist(
Notes.models.Notes.DoesNotExist: Notes matching query does not exist.
03/07/2023 12:49:24 AM : logging_confiq.logger : 
Traceback (most recent call last):
  File "C:\Users\RJ EMPIRE\Desktop\Django\FundooNotes\Notes\views.py", line 191, in put
    notes = Notes.objects.get(id=note_id, user=request.user)
            ^^^^^^^^^^^^^^^^^^^^^^^^^^^^^^^^^^^^^^^^^^^^^^^^
  File "C:\Users\RJ EMPIRE\Desktop\env\env03\Lib\site-packages\django\db\models\manager.py", line 85, in manager_method
    return getattr(self.get_queryset(), name)(*args, **kwargs)
           ^^^^^^^^^^^^^^^^^^^^^^^^^^^^^^^^^^^^^^^^^^^^^^^^^^^
  File "C:\Users\RJ EMPIRE\Desktop\env\env03\Lib\site-packages\django\db\models\query.py", line 650, in get
    raise self.model.DoesNotExist(
Notes.models.Notes.DoesNotExist: Notes matching query does not exist.
03/07/2023 12:49:24 AM : logging_confiq.logger : 
Traceback (most recent call last):
  File "C:\Users\RJ EMPIRE\Desktop\Django\FundooNotes\Notes\views.py", line 191, in put
    notes = Notes.objects.get(id=note_id, user=request.user)
            ^^^^^^^^^^^^^^^^^^^^^^^^^^^^^^^^^^^^^^^^^^^^^^^^
  File "C:\Users\RJ EMPIRE\Desktop\env\env03\Lib\site-packages\django\db\models\manager.py", line 85, in manager_method
    return getattr(self.get_queryset(), name)(*args, **kwargs)
           ^^^^^^^^^^^^^^^^^^^^^^^^^^^^^^^^^^^^^^^^^^^^^^^^^^^
  File "C:\Users\RJ EMPIRE\Desktop\env\env03\Lib\site-packages\django\db\models\query.py", line 650, in get
    raise self.model.DoesNotExist(
Notes.models.Notes.DoesNotExist: Notes matching query does not exist.
03/07/2023 12:54:29 AM : logging_confiq.logger : 
Traceback (most recent call last):
  File "C:\Users\RJ EMPIRE\Desktop\Django\FundooNotes\Notes\views.py", line 191, in put
    notes = Notes.objects.get(id=note_id, user=request.user)
            ^^^^^^^^^^^^^^^^^^^^^^^^^^^^^^^^^^^^^^^^^^^^^^^^
  File "C:\Users\RJ EMPIRE\Desktop\env\env03\Lib\site-packages\django\db\models\manager.py", line 85, in manager_method
    return getattr(self.get_queryset(), name)(*args, **kwargs)
           ^^^^^^^^^^^^^^^^^^^^^^^^^^^^^^^^^^^^^^^^^^^^^^^^^^^
  File "C:\Users\RJ EMPIRE\Desktop\env\env03\Lib\site-packages\django\db\models\query.py", line 650, in get
    raise self.model.DoesNotExist(
Notes.models.Notes.DoesNotExist: Notes matching query does not exist.
03/07/2023 12:54:29 AM : logging_confiq.logger : 
Traceback (most recent call last):
  File "C:\Users\RJ EMPIRE\Desktop\Django\FundooNotes\Notes\views.py", line 191, in put
    notes = Notes.objects.get(id=note_id, user=request.user)
            ^^^^^^^^^^^^^^^^^^^^^^^^^^^^^^^^^^^^^^^^^^^^^^^^
  File "C:\Users\RJ EMPIRE\Desktop\env\env03\Lib\site-packages\django\db\models\manager.py", line 85, in manager_method
    return getattr(self.get_queryset(), name)(*args, **kwargs)
           ^^^^^^^^^^^^^^^^^^^^^^^^^^^^^^^^^^^^^^^^^^^^^^^^^^^
  File "C:\Users\RJ EMPIRE\Desktop\env\env03\Lib\site-packages\django\db\models\query.py", line 650, in get
    raise self.model.DoesNotExist(
Notes.models.Notes.DoesNotExist: Notes matching query does not exist.
03/07/2023 12:54:29 AM : logging_confiq.logger : 
Traceback (most recent call last):
  File "C:\Users\RJ EMPIRE\Desktop\Django\FundooNotes\Notes\views.py", line 191, in put
    notes = Notes.objects.get(id=note_id, user=request.user)
            ^^^^^^^^^^^^^^^^^^^^^^^^^^^^^^^^^^^^^^^^^^^^^^^^
  File "C:\Users\RJ EMPIRE\Desktop\env\env03\Lib\site-packages\django\db\models\manager.py", line 85, in manager_method
    return getattr(self.get_queryset(), name)(*args, **kwargs)
           ^^^^^^^^^^^^^^^^^^^^^^^^^^^^^^^^^^^^^^^^^^^^^^^^^^^
  File "C:\Users\RJ EMPIRE\Desktop\env\env03\Lib\site-packages\django\db\models\query.py", line 650, in get
    raise self.model.DoesNotExist(
Notes.models.Notes.DoesNotExist: Notes matching query does not exist.
