02/22/2023 09:37:09 AM : logging_confiq.logger : 
Traceback (most recent call last):
  File "C:\Users\RJ EMPIRE\Desktop\Django\FundooNotes\Notes\views.py", line 21, in post
    serializer.is_valid(raise_exception=True)
  File "C:\Users\RJ EMPIRE\Desktop\env\env03\Lib\site-packages\rest_framework\serializers.py", line 235, in is_valid
    raise ValidationError(self.errors)
rest_framework.exceptions.ValidationError: {'user': [ErrorDetail(string='This field may not be null.', code='null')]}
02/22/2023 09:37:09 AM : logging_confiq.logger : 
Traceback (most recent call last):
  File "C:\Users\RJ EMPIRE\Desktop\Django\FundooNotes\Notes\views.py", line 21, in post
    serializer.is_valid(raise_exception=True)
  File "C:\Users\RJ EMPIRE\Desktop\env\env03\Lib\site-packages\rest_framework\serializers.py", line 235, in is_valid
    raise ValidationError(self.errors)
rest_framework.exceptions.ValidationError: {'user': [ErrorDetail(string='This field may not be null.', code='null')]}
02/22/2023 09:37:49 AM : logging_confiq.logger : 
Traceback (most recent call last):
  File "C:\Users\RJ EMPIRE\Desktop\env\env03\Lib\site-packages\django\db\models\fields\__init__.py", line 2018, in get_prep_value
    return int(value)
           ^^^^^^^^^^
  File "C:\Users\RJ EMPIRE\Desktop\env\env03\Lib\site-packages\django\contrib\auth\models.py", line 437, in __int__
    raise TypeError(
TypeError: Cannot cast AnonymousUser to int. Are you trying to use it in place of User?

The above exception was the direct cause of the following exception:

Traceback (most recent call last):
  File "C:\Users\RJ EMPIRE\Desktop\Django\FundooNotes\Notes\views.py", line 86, in get
    labels = Labels.objects.filter(user=request.user)
             ^^^^^^^^^^^^^^^^^^^^^^^^^^^^^^^^^^^^^^^^
  File "C:\Users\RJ EMPIRE\Desktop\env\env03\Lib\site-packages\django\db\models\manager.py", line 85, in manager_method
    return getattr(self.get_queryset(), name)(*args, **kwargs)
           ^^^^^^^^^^^^^^^^^^^^^^^^^^^^^^^^^^^^^^^^^^^^^^^^^^^
  File "C:\Users\RJ EMPIRE\Desktop\env\env03\Lib\site-packages\django\db\models\query.py", line 1421, in filter
    return self._filter_or_exclude(False, args, kwargs)
           ^^^^^^^^^^^^^^^^^^^^^^^^^^^^^^^^^^^^^^^^^^^^
  File "C:\Users\RJ EMPIRE\Desktop\env\env03\Lib\site-packages\django\db\models\query.py", line 1439, in _filter_or_exclude
    clone._filter_or_exclude_inplace(negate, args, kwargs)
  File "C:\Users\RJ EMPIRE\Desktop\env\env03\Lib\site-packages\django\db\models\query.py", line 1446, in _filter_or_exclude_inplace
    self._query.add_q(Q(*args, **kwargs))
  File "C:\Users\RJ EMPIRE\Desktop\env\env03\Lib\site-packages\django\db\models\sql\query.py", line 1532, in add_q
    clause, _ = self._add_q(q_object, self.used_aliases)
                ^^^^^^^^^^^^^^^^^^^^^^^^^^^^^^^^^^^^^^^^
  File "C:\Users\RJ EMPIRE\Desktop\env\env03\Lib\site-packages\django\db\models\sql\query.py", line 1562, in _add_q
    child_clause, needed_inner = self.build_filter(
                                 ^^^^^^^^^^^^^^^^^^
  File "C:\Users\RJ EMPIRE\Desktop\env\env03\Lib\site-packages\django\db\models\sql\query.py", line 1478, in build_filter
    condition = self.build_lookup(lookups, col, value)
                ^^^^^^^^^^^^^^^^^^^^^^^^^^^^^^^^^^^^^^
  File "C:\Users\RJ EMPIRE\Desktop\env\env03\Lib\site-packages\django\db\models\sql\query.py", line 1303, in build_lookup
    lookup = lookup_class(lhs, rhs)
             ^^^^^^^^^^^^^^^^^^^^^^
  File "C:\Users\RJ EMPIRE\Desktop\env\env03\Lib\site-packages\django\db\models\lookups.py", line 27, in __init__
    self.rhs = self.get_prep_lookup()
               ^^^^^^^^^^^^^^^^^^^^^^
  File "C:\Users\RJ EMPIRE\Desktop\env\env03\Lib\site-packages\django\db\models\fields\related_lookups.py", line 166, in get_prep_lookup
    self.rhs = target_field.get_prep_value(self.rhs)
               ^^^^^^^^^^^^^^^^^^^^^^^^^^^^^^^^^^^^^
  File "C:\Users\RJ EMPIRE\Desktop\env\env03\Lib\site-packages\django\db\models\fields\__init__.py", line 2020, in get_prep_value
    raise e.__class__(
TypeError: Field 'id' expected a number but got <django.contrib.auth.models.AnonymousUser object at 0x00000235DD0746D0>.
02/22/2023 09:37:49 AM : logging_confiq.logger : 
Traceback (most recent call last):
  File "C:\Users\RJ EMPIRE\Desktop\env\env03\Lib\site-packages\django\db\models\fields\__init__.py", line 2018, in get_prep_value
    return int(value)
           ^^^^^^^^^^
  File "C:\Users\RJ EMPIRE\Desktop\env\env03\Lib\site-packages\django\contrib\auth\models.py", line 437, in __int__
    raise TypeError(
TypeError: Cannot cast AnonymousUser to int. Are you trying to use it in place of User?

The above exception was the direct cause of the following exception:

Traceback (most recent call last):
  File "C:\Users\RJ EMPIRE\Desktop\Django\FundooNotes\Notes\views.py", line 86, in get
    labels = Labels.objects.filter(user=request.user)
             ^^^^^^^^^^^^^^^^^^^^^^^^^^^^^^^^^^^^^^^^
  File "C:\Users\RJ EMPIRE\Desktop\env\env03\Lib\site-packages\django\db\models\manager.py", line 85, in manager_method
    return getattr(self.get_queryset(), name)(*args, **kwargs)
           ^^^^^^^^^^^^^^^^^^^^^^^^^^^^^^^^^^^^^^^^^^^^^^^^^^^
  File "C:\Users\RJ EMPIRE\Desktop\env\env03\Lib\site-packages\django\db\models\query.py", line 1421, in filter
    return self._filter_or_exclude(False, args, kwargs)
           ^^^^^^^^^^^^^^^^^^^^^^^^^^^^^^^^^^^^^^^^^^^^
  File "C:\Users\RJ EMPIRE\Desktop\env\env03\Lib\site-packages\django\db\models\query.py", line 1439, in _filter_or_exclude
    clone._filter_or_exclude_inplace(negate, args, kwargs)
  File "C:\Users\RJ EMPIRE\Desktop\env\env03\Lib\site-packages\django\db\models\query.py", line 1446, in _filter_or_exclude_inplace
    self._query.add_q(Q(*args, **kwargs))
  File "C:\Users\RJ EMPIRE\Desktop\env\env03\Lib\site-packages\django\db\models\sql\query.py", line 1532, in add_q
    clause, _ = self._add_q(q_object, self.used_aliases)
                ^^^^^^^^^^^^^^^^^^^^^^^^^^^^^^^^^^^^^^^^
  File "C:\Users\RJ EMPIRE\Desktop\env\env03\Lib\site-packages\django\db\models\sql\query.py", line 1562, in _add_q
    child_clause, needed_inner = self.build_filter(
                                 ^^^^^^^^^^^^^^^^^^
  File "C:\Users\RJ EMPIRE\Desktop\env\env03\Lib\site-packages\django\db\models\sql\query.py", line 1478, in build_filter
    condition = self.build_lookup(lookups, col, value)
                ^^^^^^^^^^^^^^^^^^^^^^^^^^^^^^^^^^^^^^
  File "C:\Users\RJ EMPIRE\Desktop\env\env03\Lib\site-packages\django\db\models\sql\query.py", line 1303, in build_lookup
    lookup = lookup_class(lhs, rhs)
             ^^^^^^^^^^^^^^^^^^^^^^
  File "C:\Users\RJ EMPIRE\Desktop\env\env03\Lib\site-packages\django\db\models\lookups.py", line 27, in __init__
    self.rhs = self.get_prep_lookup()
               ^^^^^^^^^^^^^^^^^^^^^^
  File "C:\Users\RJ EMPIRE\Desktop\env\env03\Lib\site-packages\django\db\models\fields\related_lookups.py", line 166, in get_prep_lookup
    self.rhs = target_field.get_prep_value(self.rhs)
               ^^^^^^^^^^^^^^^^^^^^^^^^^^^^^^^^^^^^^
  File "C:\Users\RJ EMPIRE\Desktop\env\env03\Lib\site-packages\django\db\models\fields\__init__.py", line 2020, in get_prep_value
    raise e.__class__(
TypeError: Field 'id' expected a number but got <django.contrib.auth.models.AnonymousUser object at 0x00000235DD0746D0>.
02/22/2023 10:26:53 AM : logging_confiq.logger : 
Traceback (most recent call last):
  File "C:\Users\RJ EMPIRE\Desktop\env\env03\Lib\site-packages\django\db\models\fields\__init__.py", line 2018, in get_prep_value
    return int(value)
           ^^^^^^^^^^
  File "C:\Users\RJ EMPIRE\Desktop\env\env03\Lib\site-packages\django\contrib\auth\models.py", line 437, in __int__
    raise TypeError(
TypeError: Cannot cast AnonymousUser to int. Are you trying to use it in place of User?

The above exception was the direct cause of the following exception:

Traceback (most recent call last):
  File "C:\Users\RJ EMPIRE\Desktop\Django\FundooNotes\Notes\views.py", line 93, in get
    labels = Labels.objects.filter(user=request.user)
             ^^^^^^^^^^^^^^^^^^^^^^^^^^^^^^^^^^^^^^^^
  File "C:\Users\RJ EMPIRE\Desktop\env\env03\Lib\site-packages\django\db\models\manager.py", line 85, in manager_method
    return getattr(self.get_queryset(), name)(*args, **kwargs)
           ^^^^^^^^^^^^^^^^^^^^^^^^^^^^^^^^^^^^^^^^^^^^^^^^^^^
  File "C:\Users\RJ EMPIRE\Desktop\env\env03\Lib\site-packages\django\db\models\query.py", line 1421, in filter
    return self._filter_or_exclude(False, args, kwargs)
           ^^^^^^^^^^^^^^^^^^^^^^^^^^^^^^^^^^^^^^^^^^^^
  File "C:\Users\RJ EMPIRE\Desktop\env\env03\Lib\site-packages\django\db\models\query.py", line 1439, in _filter_or_exclude
    clone._filter_or_exclude_inplace(negate, args, kwargs)
  File "C:\Users\RJ EMPIRE\Desktop\env\env03\Lib\site-packages\django\db\models\query.py", line 1446, in _filter_or_exclude_inplace
    self._query.add_q(Q(*args, **kwargs))
  File "C:\Users\RJ EMPIRE\Desktop\env\env03\Lib\site-packages\django\db\models\sql\query.py", line 1532, in add_q
    clause, _ = self._add_q(q_object, self.used_aliases)
                ^^^^^^^^^^^^^^^^^^^^^^^^^^^^^^^^^^^^^^^^
  File "C:\Users\RJ EMPIRE\Desktop\env\env03\Lib\site-packages\django\db\models\sql\query.py", line 1562, in _add_q
    child_clause, needed_inner = self.build_filter(
                                 ^^^^^^^^^^^^^^^^^^
  File "C:\Users\RJ EMPIRE\Desktop\env\env03\Lib\site-packages\django\db\models\sql\query.py", line 1478, in build_filter
    condition = self.build_lookup(lookups, col, value)
                ^^^^^^^^^^^^^^^^^^^^^^^^^^^^^^^^^^^^^^
  File "C:\Users\RJ EMPIRE\Desktop\env\env03\Lib\site-packages\django\db\models\sql\query.py", line 1303, in build_lookup
    lookup = lookup_class(lhs, rhs)
             ^^^^^^^^^^^^^^^^^^^^^^
  File "C:\Users\RJ EMPIRE\Desktop\env\env03\Lib\site-packages\django\db\models\lookups.py", line 27, in __init__
    self.rhs = self.get_prep_lookup()
               ^^^^^^^^^^^^^^^^^^^^^^
  File "C:\Users\RJ EMPIRE\Desktop\env\env03\Lib\site-packages\django\db\models\fields\related_lookups.py", line 166, in get_prep_lookup
    self.rhs = target_field.get_prep_value(self.rhs)
               ^^^^^^^^^^^^^^^^^^^^^^^^^^^^^^^^^^^^^
  File "C:\Users\RJ EMPIRE\Desktop\env\env03\Lib\site-packages\django\db\models\fields\__init__.py", line 2020, in get_prep_value
    raise e.__class__(
TypeError: Field 'id' expected a number but got <django.contrib.auth.models.AnonymousUser object at 0x0000029F2B76B650>.
02/22/2023 10:26:53 AM : logging_confiq.logger : 
Traceback (most recent call last):
  File "C:\Users\RJ EMPIRE\Desktop\env\env03\Lib\site-packages\django\db\models\fields\__init__.py", line 2018, in get_prep_value
    return int(value)
           ^^^^^^^^^^
  File "C:\Users\RJ EMPIRE\Desktop\env\env03\Lib\site-packages\django\contrib\auth\models.py", line 437, in __int__
    raise TypeError(
TypeError: Cannot cast AnonymousUser to int. Are you trying to use it in place of User?

The above exception was the direct cause of the following exception:

Traceback (most recent call last):
  File "C:\Users\RJ EMPIRE\Desktop\Django\FundooNotes\Notes\views.py", line 93, in get
    labels = Labels.objects.filter(user=request.user)
             ^^^^^^^^^^^^^^^^^^^^^^^^^^^^^^^^^^^^^^^^
  File "C:\Users\RJ EMPIRE\Desktop\env\env03\Lib\site-packages\django\db\models\manager.py", line 85, in manager_method
    return getattr(self.get_queryset(), name)(*args, **kwargs)
           ^^^^^^^^^^^^^^^^^^^^^^^^^^^^^^^^^^^^^^^^^^^^^^^^^^^
  File "C:\Users\RJ EMPIRE\Desktop\env\env03\Lib\site-packages\django\db\models\query.py", line 1421, in filter
    return self._filter_or_exclude(False, args, kwargs)
           ^^^^^^^^^^^^^^^^^^^^^^^^^^^^^^^^^^^^^^^^^^^^
  File "C:\Users\RJ EMPIRE\Desktop\env\env03\Lib\site-packages\django\db\models\query.py", line 1439, in _filter_or_exclude
    clone._filter_or_exclude_inplace(negate, args, kwargs)
  File "C:\Users\RJ EMPIRE\Desktop\env\env03\Lib\site-packages\django\db\models\query.py", line 1446, in _filter_or_exclude_inplace
    self._query.add_q(Q(*args, **kwargs))
  File "C:\Users\RJ EMPIRE\Desktop\env\env03\Lib\site-packages\django\db\models\sql\query.py", line 1532, in add_q
    clause, _ = self._add_q(q_object, self.used_aliases)
                ^^^^^^^^^^^^^^^^^^^^^^^^^^^^^^^^^^^^^^^^
  File "C:\Users\RJ EMPIRE\Desktop\env\env03\Lib\site-packages\django\db\models\sql\query.py", line 1562, in _add_q
    child_clause, needed_inner = self.build_filter(
                                 ^^^^^^^^^^^^^^^^^^
  File "C:\Users\RJ EMPIRE\Desktop\env\env03\Lib\site-packages\django\db\models\sql\query.py", line 1478, in build_filter
    condition = self.build_lookup(lookups, col, value)
                ^^^^^^^^^^^^^^^^^^^^^^^^^^^^^^^^^^^^^^
  File "C:\Users\RJ EMPIRE\Desktop\env\env03\Lib\site-packages\django\db\models\sql\query.py", line 1303, in build_lookup
    lookup = lookup_class(lhs, rhs)
             ^^^^^^^^^^^^^^^^^^^^^^
  File "C:\Users\RJ EMPIRE\Desktop\env\env03\Lib\site-packages\django\db\models\lookups.py", line 27, in __init__
    self.rhs = self.get_prep_lookup()
               ^^^^^^^^^^^^^^^^^^^^^^
  File "C:\Users\RJ EMPIRE\Desktop\env\env03\Lib\site-packages\django\db\models\fields\related_lookups.py", line 166, in get_prep_lookup
    self.rhs = target_field.get_prep_value(self.rhs)
               ^^^^^^^^^^^^^^^^^^^^^^^^^^^^^^^^^^^^^
  File "C:\Users\RJ EMPIRE\Desktop\env\env03\Lib\site-packages\django\db\models\fields\__init__.py", line 2020, in get_prep_value
    raise e.__class__(
TypeError: Field 'id' expected a number but got <django.contrib.auth.models.AnonymousUser object at 0x0000029F2B76B650>.
