02/21/2023 09:23:16 AM : logging_confiq.logger : 
Traceback (most recent call last):
  File "C:\Users\RJ EMPIRE\Desktop\Django\FundooNotes\Notes\views.py", line 98, in put
    serializer.is_valid(raise_exception=True)
  File "C:\Users\RJ EMPIRE\Desktop\env\env03\Lib\site-packages\rest_framework\serializers.py", line 227, in is_valid
    self._validated_data = self.run_validation(self.initial_data)
                           ^^^^^^^^^^^^^^^^^^^^^^^^^^^^^^^^^^^^^^
  File "C:\Users\RJ EMPIRE\Desktop\env\env03\Lib\site-packages\rest_framework\serializers.py", line 426, in run_validation
    value = self.to_internal_value(data)
            ^^^^^^^^^^^^^^^^^^^^^^^^^^^^
  File "C:\Users\RJ EMPIRE\Desktop\env\env03\Lib\site-packages\rest_framework\serializers.py", line 483, in to_internal_value
    validated_value = field.run_validation(primitive_value)
                      ^^^^^^^^^^^^^^^^^^^^^^^^^^^^^^^^^^^^^
  File "C:\Users\RJ EMPIRE\Desktop\env\env03\Lib\site-packages\rest_framework\fields.py", line 544, in run_validation
    (is_empty_value, data) = self.validate_empty_values(data)
                             ^^^^^^^^^^^^^^^^^^^^^^^^^^^^^^^^
  File "C:\Users\RJ EMPIRE\Desktop\env\env03\Lib\site-packages\rest_framework\fields.py", line 520, in validate_empty_values
    return (True, self.get_default())
                  ^^^^^^^^^^^^^^^^^^
  File "C:\Users\RJ EMPIRE\Desktop\env\env03\Lib\site-packages\rest_framework\fields.py", line 495, in get_default
    return self.default(self)
           ^^^^^^^^^^^^^^^^^^
  File "C:\Users\RJ EMPIRE\Desktop\env\env03\Lib\site-packages\rest_framework\fields.py", line 279, in __call__
    return serializer_field.context['request'].user
           ~~~~~~~~~~~~~~~~~~~~~~~~^^^^^^^^^^^
KeyError: 'request'
02/21/2023 09:23:16 AM : logging_confiq.logger : 
Traceback (most recent call last):
  File "C:\Users\RJ EMPIRE\Desktop\Django\FundooNotes\Notes\views.py", line 98, in put
    serializer.is_valid(raise_exception=True)
  File "C:\Users\RJ EMPIRE\Desktop\env\env03\Lib\site-packages\rest_framework\serializers.py", line 227, in is_valid
    self._validated_data = self.run_validation(self.initial_data)
                           ^^^^^^^^^^^^^^^^^^^^^^^^^^^^^^^^^^^^^^
  File "C:\Users\RJ EMPIRE\Desktop\env\env03\Lib\site-packages\rest_framework\serializers.py", line 426, in run_validation
    value = self.to_internal_value(data)
            ^^^^^^^^^^^^^^^^^^^^^^^^^^^^
  File "C:\Users\RJ EMPIRE\Desktop\env\env03\Lib\site-packages\rest_framework\serializers.py", line 483, in to_internal_value
    validated_value = field.run_validation(primitive_value)
                      ^^^^^^^^^^^^^^^^^^^^^^^^^^^^^^^^^^^^^
  File "C:\Users\RJ EMPIRE\Desktop\env\env03\Lib\site-packages\rest_framework\fields.py", line 544, in run_validation
    (is_empty_value, data) = self.validate_empty_values(data)
                             ^^^^^^^^^^^^^^^^^^^^^^^^^^^^^^^^
  File "C:\Users\RJ EMPIRE\Desktop\env\env03\Lib\site-packages\rest_framework\fields.py", line 520, in validate_empty_values
    return (True, self.get_default())
                  ^^^^^^^^^^^^^^^^^^
  File "C:\Users\RJ EMPIRE\Desktop\env\env03\Lib\site-packages\rest_framework\fields.py", line 495, in get_default
    return self.default(self)
           ^^^^^^^^^^^^^^^^^^
  File "C:\Users\RJ EMPIRE\Desktop\env\env03\Lib\site-packages\rest_framework\fields.py", line 279, in __call__
    return serializer_field.context['request'].user
           ~~~~~~~~~~~~~~~~~~~~~~~~^^^^^^^^^^^
KeyError: 'request'
02/21/2023 09:46:00 AM : logging_confiq.logger : 
Traceback (most recent call last):
  File "C:\Users\RJ EMPIRE\Desktop\Django\FundooNotes\Notes\views.py", line 74, in post
    serializer = DisplayLabelsSerializer(data=request.data, user=request.user)
                 ^^^^^^^^^^^^^^^^^^^^^^^^^^^^^^^^^^^^^^^^^^^^^^^^^^^^^^^^^^^^^
  File "C:\Users\RJ EMPIRE\Desktop\env\env03\Lib\site-packages\rest_framework\serializers.py", line 116, in __init__
    super().__init__(**kwargs)
TypeError: Field.__init__() got an unexpected keyword argument 'user'
02/21/2023 09:46:00 AM : logging_confiq.logger : 
Traceback (most recent call last):
  File "C:\Users\RJ EMPIRE\Desktop\Django\FundooNotes\Notes\views.py", line 74, in post
    serializer = DisplayLabelsSerializer(data=request.data, user=request.user)
                 ^^^^^^^^^^^^^^^^^^^^^^^^^^^^^^^^^^^^^^^^^^^^^^^^^^^^^^^^^^^^^
  File "C:\Users\RJ EMPIRE\Desktop\env\env03\Lib\site-packages\rest_framework\serializers.py", line 116, in __init__
    super().__init__(**kwargs)
TypeError: Field.__init__() got an unexpected keyword argument 'user'
02/21/2023 09:50:35 AM : logging_confiq.logger : 
Traceback (most recent call last):
  File "C:\Users\RJ EMPIRE\Desktop\Django\FundooNotes\Notes\views.py", line 74, in post
    serializer = DisplayLabelsSerializer(data=request.data, user=request.user)
                 ^^^^^^^^^^^^^^^^^^^^^^^^^^^^^^^^^^^^^^^^^^^^^^^^^^^^^^^^^^^^^
  File "C:\Users\RJ EMPIRE\Desktop\env\env03\Lib\site-packages\rest_framework\serializers.py", line 116, in __init__
    super().__init__(**kwargs)
TypeError: Field.__init__() got an unexpected keyword argument 'user'
02/21/2023 09:50:35 AM : logging_confiq.logger : 
Traceback (most recent call last):
  File "C:\Users\RJ EMPIRE\Desktop\Django\FundooNotes\Notes\views.py", line 74, in post
    serializer = DisplayLabelsSerializer(data=request.data, user=request.user)
                 ^^^^^^^^^^^^^^^^^^^^^^^^^^^^^^^^^^^^^^^^^^^^^^^^^^^^^^^^^^^^^
  File "C:\Users\RJ EMPIRE\Desktop\env\env03\Lib\site-packages\rest_framework\serializers.py", line 116, in __init__
    super().__init__(**kwargs)
TypeError: Field.__init__() got an unexpected keyword argument 'user'
02/21/2023 09:50:37 AM : logging_confiq.logger : 
Traceback (most recent call last):
  File "C:\Users\RJ EMPIRE\Desktop\Django\FundooNotes\Notes\views.py", line 74, in post
    serializer = DisplayLabelsSerializer(data=request.data, user=request.user)
                 ^^^^^^^^^^^^^^^^^^^^^^^^^^^^^^^^^^^^^^^^^^^^^^^^^^^^^^^^^^^^^
  File "C:\Users\RJ EMPIRE\Desktop\env\env03\Lib\site-packages\rest_framework\serializers.py", line 116, in __init__
    super().__init__(**kwargs)
TypeError: Field.__init__() got an unexpected keyword argument 'user'
02/21/2023 09:50:37 AM : logging_confiq.logger : 
Traceback (most recent call last):
  File "C:\Users\RJ EMPIRE\Desktop\Django\FundooNotes\Notes\views.py", line 74, in post
    serializer = DisplayLabelsSerializer(data=request.data, user=request.user)
                 ^^^^^^^^^^^^^^^^^^^^^^^^^^^^^^^^^^^^^^^^^^^^^^^^^^^^^^^^^^^^^
  File "C:\Users\RJ EMPIRE\Desktop\env\env03\Lib\site-packages\rest_framework\serializers.py", line 116, in __init__
    super().__init__(**kwargs)
TypeError: Field.__init__() got an unexpected keyword argument 'user'
02/21/2023 10:28:09 AM : logging_confiq.logger : 
Traceback (most recent call last):
  File "C:\Users\RJ EMPIRE\Desktop\Django\FundooNotes\Notes\views.py", line 111, in delete
    labels = Labels.objects.get(name=label_name, user=request.user)
             ^^^^^^^^^^^^^^^^^^^^^^^^^^^^^^^^^^^^^^^^^^^^^^^^^^^^^^
  File "C:\Users\RJ EMPIRE\Desktop\env\env03\Lib\site-packages\django\db\models\manager.py", line 85, in manager_method
    return getattr(self.get_queryset(), name)(*args, **kwargs)
           ^^^^^^^^^^^^^^^^^^^^^^^^^^^^^^^^^^^^^^^^^^^^^^^^^^^
  File "C:\Users\RJ EMPIRE\Desktop\env\env03\Lib\site-packages\django\db\models\query.py", line 650, in get
    raise self.model.DoesNotExist(
Notes.models.Labels.DoesNotExist: Labels matching query does not exist.
02/21/2023 10:28:09 AM : logging_confiq.logger : 
Traceback (most recent call last):
  File "C:\Users\RJ EMPIRE\Desktop\Django\FundooNotes\Notes\views.py", line 111, in delete
    labels = Labels.objects.get(name=label_name, user=request.user)
             ^^^^^^^^^^^^^^^^^^^^^^^^^^^^^^^^^^^^^^^^^^^^^^^^^^^^^^
  File "C:\Users\RJ EMPIRE\Desktop\env\env03\Lib\site-packages\django\db\models\manager.py", line 85, in manager_method
    return getattr(self.get_queryset(), name)(*args, **kwargs)
           ^^^^^^^^^^^^^^^^^^^^^^^^^^^^^^^^^^^^^^^^^^^^^^^^^^^
  File "C:\Users\RJ EMPIRE\Desktop\env\env03\Lib\site-packages\django\db\models\query.py", line 650, in get
    raise self.model.DoesNotExist(
Notes.models.Labels.DoesNotExist: Labels matching query does not exist.
02/21/2023 10:31:01 AM : logging_confiq.logger : 
Traceback (most recent call last):
  File "C:\Users\RJ EMPIRE\Desktop\Django\FundooNotes\Notes\views.py", line 111, in delete
    labels = Labels.objects.get(name=label_name, user=request.user)
             ^^^^^^^^^^^^^^^^^^^^^^^^^^^^^^^^^^^^^^^^^^^^^^^^^^^^^^
  File "C:\Users\RJ EMPIRE\Desktop\env\env03\Lib\site-packages\django\db\models\manager.py", line 85, in manager_method
    return getattr(self.get_queryset(), name)(*args, **kwargs)
           ^^^^^^^^^^^^^^^^^^^^^^^^^^^^^^^^^^^^^^^^^^^^^^^^^^^
  File "C:\Users\RJ EMPIRE\Desktop\env\env03\Lib\site-packages\django\db\models\query.py", line 650, in get
    raise self.model.DoesNotExist(
Notes.models.Labels.DoesNotExist: Labels matching query does not exist.
02/21/2023 10:31:01 AM : logging_confiq.logger : 
Traceback (most recent call last):
  File "C:\Users\RJ EMPIRE\Desktop\Django\FundooNotes\Notes\views.py", line 111, in delete
    labels = Labels.objects.get(name=label_name, user=request.user)
             ^^^^^^^^^^^^^^^^^^^^^^^^^^^^^^^^^^^^^^^^^^^^^^^^^^^^^^
  File "C:\Users\RJ EMPIRE\Desktop\env\env03\Lib\site-packages\django\db\models\manager.py", line 85, in manager_method
    return getattr(self.get_queryset(), name)(*args, **kwargs)
           ^^^^^^^^^^^^^^^^^^^^^^^^^^^^^^^^^^^^^^^^^^^^^^^^^^^
  File "C:\Users\RJ EMPIRE\Desktop\env\env03\Lib\site-packages\django\db\models\query.py", line 650, in get
    raise self.model.DoesNotExist(
Notes.models.Labels.DoesNotExist: Labels matching query does not exist.
